2024-01-26 21:38:28,025 (WARNING) - django.request - Not Found: /api/iot/ws/
2024-01-26 21:38:32,060 (ERROR) - django.request - Internal Server Error: /api/iot/ws/AC118/
Traceback (most recent call last):
  File "/home/sabbir/zenith-sys/zenith/.venv/lib/python3.10/site-packages/django/db/models/fields/__init__.py", line 2053, in get_prep_value
    return int(value)
ValueError: invalid literal for int() with base 10: 'AC118'

The above exception was the direct cause of the following exception:

Traceback (most recent call last):
  File "/home/sabbir/zenith-sys/zenith/.venv/lib/python3.10/site-packages/asgiref/sync.py", line 534, in thread_handler
    raise exc_info[1]
  File "/home/sabbir/zenith-sys/zenith/.venv/lib/python3.10/site-packages/django/core/handlers/exception.py", line 42, in inner
    response = await get_response(request)
  File "/home/sabbir/zenith-sys/zenith/.venv/lib/python3.10/site-packages/django/core/handlers/base.py", line 253, in _get_response_async
    response = await wrapped_callback(
  File "/home/sabbir/zenith-sys/zenith/.venv/lib/python3.10/site-packages/asgiref/sync.py", line 479, in __call__
    ret: _R = await loop.run_in_executor(
  File "/home/sabbir/zenith-sys/zenith/.venv/lib/python3.10/site-packages/asgiref/current_thread_executor.py", line 40, in run
    result = self.fn(*self.args, **self.kwargs)
  File "/home/sabbir/zenith-sys/zenith/.venv/lib/python3.10/site-packages/asgiref/sync.py", line 538, in thread_handler
    return func(*args, **kwargs)
  File "/home/sabbir/zenith-sys/zenith/.venv/lib/python3.10/site-packages/django/views/generic/base.py", line 104, in view
    return self.dispatch(request, *args, **kwargs)
  File "/home/sabbir/zenith-sys/zenith/.venv/lib/python3.10/site-packages/django/views/generic/base.py", line 143, in dispatch
    return handler(request, *args, **kwargs)
  File "/home/sabbir/zenith-sys/zenith/.venv/lib/python3.10/site-packages/django/views/generic/base.py", line 226, in get
    context = self.get_context_data(**kwargs)
  File "/home/sabbir/zenith-sys/zenith/iot/views.py", line 44, in get_context_data
    topic = Device.objects.get(pk=self.kwargs["device_id"]).topic
  File "/home/sabbir/zenith-sys/zenith/.venv/lib/python3.10/site-packages/django/db/models/manager.py", line 87, in manager_method
    return getattr(self.get_queryset(), name)(*args, **kwargs)
  File "/home/sabbir/zenith-sys/zenith/.venv/lib/python3.10/site-packages/django/db/models/query.py", line 623, in get
    clone = self._chain() if self.query.combinator else self.filter(*args, **kwargs)
  File "/home/sabbir/zenith-sys/zenith/.venv/lib/python3.10/site-packages/django/db/models/query.py", line 1436, in filter
    return self._filter_or_exclude(False, args, kwargs)
  File "/home/sabbir/zenith-sys/zenith/.venv/lib/python3.10/site-packages/django/db/models/query.py", line 1454, in _filter_or_exclude
    clone._filter_or_exclude_inplace(negate, args, kwargs)
  File "/home/sabbir/zenith-sys/zenith/.venv/lib/python3.10/site-packages/django/db/models/query.py", line 1461, in _filter_or_exclude_inplace
    self._query.add_q(Q(*args, **kwargs))
  File "/home/sabbir/zenith-sys/zenith/.venv/lib/python3.10/site-packages/django/db/models/sql/query.py", line 1545, in add_q
    clause, _ = self._add_q(q_object, self.used_aliases)
  File "/home/sabbir/zenith-sys/zenith/.venv/lib/python3.10/site-packages/django/db/models/sql/query.py", line 1576, in _add_q
    child_clause, needed_inner = self.build_filter(
  File "/home/sabbir/zenith-sys/zenith/.venv/lib/python3.10/site-packages/django/db/models/sql/query.py", line 1491, in build_filter
    condition = self.build_lookup(lookups, col, value)
  File "/home/sabbir/zenith-sys/zenith/.venv/lib/python3.10/site-packages/django/db/models/sql/query.py", line 1318, in build_lookup
    lookup = lookup_class(lhs, rhs)
  File "/home/sabbir/zenith-sys/zenith/.venv/lib/python3.10/site-packages/django/db/models/lookups.py", line 27, in __init__
    self.rhs = self.get_prep_lookup()
  File "/home/sabbir/zenith-sys/zenith/.venv/lib/python3.10/site-packages/django/db/models/lookups.py", line 341, in get_prep_lookup
    return super().get_prep_lookup()
  File "/home/sabbir/zenith-sys/zenith/.venv/lib/python3.10/site-packages/django/db/models/lookups.py", line 85, in get_prep_lookup
    return self.lhs.output_field.get_prep_value(self.rhs)
  File "/home/sabbir/zenith-sys/zenith/.venv/lib/python3.10/site-packages/django/db/models/fields/__init__.py", line 2055, in get_prep_value
    raise e.__class__(
ValueError: Field 'id' expected a number but got 'AC118'.
2024-01-26 21:45:07,950 (ERROR) - django.request - Internal Server Error: /api/iot/ws/AC118/
Traceback (most recent call last):
  File "/home/sabbir/zenith-sys/zenith/.venv/lib/python3.10/site-packages/asgiref/sync.py", line 534, in thread_handler
    raise exc_info[1]
  File "/home/sabbir/zenith-sys/zenith/.venv/lib/python3.10/site-packages/django/core/handlers/exception.py", line 42, in inner
    response = await get_response(request)
  File "/home/sabbir/zenith-sys/zenith/.venv/lib/python3.10/site-packages/django/core/handlers/base.py", line 253, in _get_response_async
    response = await wrapped_callback(
  File "/home/sabbir/zenith-sys/zenith/.venv/lib/python3.10/site-packages/asgiref/sync.py", line 479, in __call__
    ret: _R = await loop.run_in_executor(
  File "/home/sabbir/zenith-sys/zenith/.venv/lib/python3.10/site-packages/asgiref/current_thread_executor.py", line 40, in run
    result = self.fn(*self.args, **self.kwargs)
  File "/home/sabbir/zenith-sys/zenith/.venv/lib/python3.10/site-packages/asgiref/sync.py", line 538, in thread_handler
    return func(*args, **kwargs)
  File "/home/sabbir/zenith-sys/zenith/.venv/lib/python3.10/site-packages/django/views/generic/base.py", line 104, in view
    return self.dispatch(request, *args, **kwargs)
  File "/home/sabbir/zenith-sys/zenith/.venv/lib/python3.10/site-packages/django/views/generic/base.py", line 143, in dispatch
    return handler(request, *args, **kwargs)
  File "/home/sabbir/zenith-sys/zenith/.venv/lib/python3.10/site-packages/django/views/generic/base.py", line 226, in get
    context = self.get_context_data(**kwargs)
  File "/home/sabbir/zenith-sys/zenith/iot/views.py", line 46, in get_context_data
    mqtt_client.on_message = self.on_message
AttributeError: 'IoTChannel' object has no attribute 'on_message'
2024-01-26 21:45:50,382 (ERROR) - django.request - Internal Server Error: /api/iot/ws/AC118/
Traceback (most recent call last):
  File "/home/sabbir/zenith-sys/zenith/.venv/lib/python3.10/site-packages/asgiref/sync.py", line 534, in thread_handler
    raise exc_info[1]
  File "/home/sabbir/zenith-sys/zenith/.venv/lib/python3.10/site-packages/django/core/handlers/exception.py", line 42, in inner
    response = await get_response(request)
  File "/home/sabbir/zenith-sys/zenith/.venv/lib/python3.10/site-packages/django/core/handlers/base.py", line 253, in _get_response_async
    response = await wrapped_callback(
  File "/home/sabbir/zenith-sys/zenith/.venv/lib/python3.10/site-packages/asgiref/sync.py", line 479, in __call__
    ret: _R = await loop.run_in_executor(
  File "/home/sabbir/zenith-sys/zenith/.venv/lib/python3.10/site-packages/asgiref/current_thread_executor.py", line 40, in run
    result = self.fn(*self.args, **self.kwargs)
  File "/home/sabbir/zenith-sys/zenith/.venv/lib/python3.10/site-packages/asgiref/sync.py", line 538, in thread_handler
    return func(*args, **kwargs)
  File "/home/sabbir/zenith-sys/zenith/.venv/lib/python3.10/site-packages/django/views/generic/base.py", line 104, in view
    return self.dispatch(request, *args, **kwargs)
  File "/home/sabbir/zenith-sys/zenith/.venv/lib/python3.10/site-packages/django/views/generic/base.py", line 143, in dispatch
    return handler(request, *args, **kwargs)
  File "/home/sabbir/zenith-sys/zenith/.venv/lib/python3.10/site-packages/django/views/generic/base.py", line 226, in get
    context = self.get_context_data(**kwargs)
  File "/home/sabbir/zenith-sys/zenith/iot/views.py", line 46, in get_context_data
    data = mqtt_client.get_message()
AttributeError: 'Client' object has no attribute 'get_message'. Did you mean: '_on_message'?
2024-01-26 21:46:04,973 (ERROR) - django.request - Internal Server Error: /api/iot/ws/AC118/
Traceback (most recent call last):
  File "/home/sabbir/zenith-sys/zenith/.venv/lib/python3.10/site-packages/asgiref/sync.py", line 534, in thread_handler
    raise exc_info[1]
  File "/home/sabbir/zenith-sys/zenith/.venv/lib/python3.10/site-packages/django/core/handlers/exception.py", line 42, in inner
    response = await get_response(request)
  File "/home/sabbir/zenith-sys/zenith/.venv/lib/python3.10/site-packages/django/core/handlers/base.py", line 253, in _get_response_async
    response = await wrapped_callback(
  File "/home/sabbir/zenith-sys/zenith/.venv/lib/python3.10/site-packages/asgiref/sync.py", line 479, in __call__
    ret: _R = await loop.run_in_executor(
  File "/home/sabbir/zenith-sys/zenith/.venv/lib/python3.10/site-packages/asgiref/current_thread_executor.py", line 40, in run
    result = self.fn(*self.args, **self.kwargs)
  File "/home/sabbir/zenith-sys/zenith/.venv/lib/python3.10/site-packages/asgiref/sync.py", line 538, in thread_handler
    return func(*args, **kwargs)
  File "/home/sabbir/zenith-sys/zenith/.venv/lib/python3.10/site-packages/django/views/generic/base.py", line 104, in view
    return self.dispatch(request, *args, **kwargs)
  File "/home/sabbir/zenith-sys/zenith/.venv/lib/python3.10/site-packages/django/views/generic/base.py", line 143, in dispatch
    return handler(request, *args, **kwargs)
  File "/home/sabbir/zenith-sys/zenith/.venv/lib/python3.10/site-packages/django/views/generic/base.py", line 226, in get
    context = self.get_context_data(**kwargs)
  File "/home/sabbir/zenith-sys/zenith/iot/views.py", line 46, in get_context_data
    data = mqtt_client.on_message()
TypeError: on_message() missing 3 required positional arguments: 'client', 'userdata', and 'msg'
2024-01-26 22:04:33,284 (ERROR) - django.request - Internal Server Error: /api/iot/ws/AC118/
Traceback (most recent call last):
  File "/home/sabbir/zenith-sys/zenith/.venv/lib/python3.10/site-packages/asgiref/sync.py", line 534, in thread_handler
    raise exc_info[1]
  File "/home/sabbir/zenith-sys/zenith/.venv/lib/python3.10/site-packages/django/core/handlers/exception.py", line 42, in inner
    response = await get_response(request)
  File "/home/sabbir/zenith-sys/zenith/.venv/lib/python3.10/site-packages/django/core/handlers/base.py", line 235, in _get_response_async
    callback, callback_args, callback_kwargs = self.resolve_request(request)
  File "/home/sabbir/zenith-sys/zenith/.venv/lib/python3.10/site-packages/django/core/handlers/base.py", line 313, in resolve_request
    resolver_match = resolver.resolve(request.path_info)
  File "/home/sabbir/zenith-sys/zenith/.venv/lib/python3.10/site-packages/django/urls/resolvers.py", line 663, in resolve
    for pattern in self.url_patterns:
  File "/home/sabbir/zenith-sys/zenith/.venv/lib/python3.10/site-packages/django/utils/functional.py", line 57, in __get__
    res = instance.__dict__[self.name] = self.func(instance)
  File "/home/sabbir/zenith-sys/zenith/.venv/lib/python3.10/site-packages/django/urls/resolvers.py", line 715, in url_patterns
    patterns = getattr(self.urlconf_module, "urlpatterns", self.urlconf_module)
  File "/home/sabbir/zenith-sys/zenith/.venv/lib/python3.10/site-packages/django/utils/functional.py", line 57, in __get__
    res = instance.__dict__[self.name] = self.func(instance)
  File "/home/sabbir/zenith-sys/zenith/.venv/lib/python3.10/site-packages/django/urls/resolvers.py", line 708, in urlconf_module
    return import_module(self.urlconf_name)
  File "/usr/lib/python3.10/importlib/__init__.py", line 126, in import_module
    return _bootstrap._gcd_import(name[level:], package, level)
  File "<frozen importlib._bootstrap>", line 1050, in _gcd_import
  File "<frozen importlib._bootstrap>", line 1027, in _find_and_load
  File "<frozen importlib._bootstrap>", line 1006, in _find_and_load_unlocked
  File "<frozen importlib._bootstrap>", line 688, in _load_unlocked
  File "<frozen importlib._bootstrap_external>", line 883, in exec_module
  File "<frozen importlib._bootstrap>", line 241, in _call_with_frames_removed
  File "/home/sabbir/zenith-sys/zenith/core/urls.py", line 22, in <module>
    path("api/iot/", include("iot.urls"), name="iot"),
  File "/home/sabbir/zenith-sys/zenith/.venv/lib/python3.10/site-packages/django/urls/conf.py", line 38, in include
    urlconf_module = import_module(urlconf_module)
  File "/usr/lib/python3.10/importlib/__init__.py", line 126, in import_module
    return _bootstrap._gcd_import(name[level:], package, level)
  File "<frozen importlib._bootstrap>", line 1050, in _gcd_import
  File "<frozen importlib._bootstrap>", line 1027, in _find_and_load
  File "<frozen importlib._bootstrap>", line 1006, in _find_and_load_unlocked
  File "<frozen importlib._bootstrap>", line 688, in _load_unlocked
  File "<frozen importlib._bootstrap_external>", line 883, in exec_module
  File "<frozen importlib._bootstrap>", line 241, in _call_with_frames_removed
  File "/home/sabbir/zenith-sys/zenith/iot/urls.py", line 3, in <module>
    from iot.views import (
  File "/home/sabbir/zenith-sys/zenith/iot/views.py", line 16, in <module>
    from iot.mqtt.client import subscribe_to_topic
  File "/home/sabbir/zenith-sys/zenith/iot/mqtt/__init__.py", line 1, in <module>
    from iot.mqtt.client import client
ImportError: cannot import name 'client' from 'iot.mqtt.client' (/home/sabbir/zenith-sys/zenith/iot/mqtt/client.py)
2024-01-27 06:47:39,357 (WARNING) - django.request - Not Found: /favicon.ico
2024-01-27 07:00:25,111 (ERROR) - django.request - Internal Server Error: /api/iot/ws/AC118/
Traceback (most recent call last):
  File "/home/sabbir/zenith-sys/zenith/.venv/lib/python3.10/site-packages/asgiref/sync.py", line 534, in thread_handler
    raise exc_info[1]
  File "/home/sabbir/zenith-sys/zenith/.venv/lib/python3.10/site-packages/django/core/handlers/exception.py", line 42, in inner
    response = await get_response(request)
  File "/home/sabbir/zenith-sys/zenith/.venv/lib/python3.10/site-packages/django/core/handlers/base.py", line 253, in _get_response_async
    response = await wrapped_callback(
  File "/home/sabbir/zenith-sys/zenith/.venv/lib/python3.10/site-packages/asgiref/sync.py", line 479, in __call__
    ret: _R = await loop.run_in_executor(
  File "/home/sabbir/zenith-sys/zenith/.venv/lib/python3.10/site-packages/asgiref/current_thread_executor.py", line 40, in run
    result = self.fn(*self.args, **self.kwargs)
  File "/home/sabbir/zenith-sys/zenith/.venv/lib/python3.10/site-packages/asgiref/sync.py", line 538, in thread_handler
    return func(*args, **kwargs)
  File "/home/sabbir/zenith-sys/zenith/.venv/lib/python3.10/site-packages/django/views/generic/base.py", line 104, in view
    return self.dispatch(request, *args, **kwargs)
  File "/home/sabbir/zenith-sys/zenith/.venv/lib/python3.10/site-packages/django/views/generic/base.py", line 143, in dispatch
    return handler(request, *args, **kwargs)
  File "/home/sabbir/zenith-sys/zenith/.venv/lib/python3.10/site-packages/django/views/generic/base.py", line 226, in get
    context = self.get_context_data(**kwargs)
  File "/home/sabbir/zenith-sys/zenith/iot/views.py", line 55, in get_context_data
    "message": f"{mqtt_client.on_message()}",
TypeError: on_message() missing 3 required positional arguments: 'client', 'userdata', and 'msg'
2024-01-27 07:05:52,739 (ERROR) - django.request - Internal Server Error: /api/iot/ws/AC118/
Traceback (most recent call last):
  File "/home/sabbir/zenith-sys/zenith/.venv/lib/python3.10/site-packages/asgiref/sync.py", line 534, in thread_handler
    raise exc_info[1]
  File "/home/sabbir/zenith-sys/zenith/.venv/lib/python3.10/site-packages/django/core/handlers/exception.py", line 42, in inner
    response = await get_response(request)
  File "/home/sabbir/zenith-sys/zenith/.venv/lib/python3.10/site-packages/django/core/handlers/base.py", line 253, in _get_response_async
    response = await wrapped_callback(
  File "/home/sabbir/zenith-sys/zenith/.venv/lib/python3.10/site-packages/asgiref/sync.py", line 479, in __call__
    ret: _R = await loop.run_in_executor(
  File "/home/sabbir/zenith-sys/zenith/.venv/lib/python3.10/site-packages/asgiref/current_thread_executor.py", line 40, in run
    result = self.fn(*self.args, **self.kwargs)
  File "/home/sabbir/zenith-sys/zenith/.venv/lib/python3.10/site-packages/asgiref/sync.py", line 538, in thread_handler
    return func(*args, **kwargs)
  File "/home/sabbir/zenith-sys/zenith/.venv/lib/python3.10/site-packages/django/views/generic/base.py", line 104, in view
    return self.dispatch(request, *args, **kwargs)
  File "/home/sabbir/zenith-sys/zenith/.venv/lib/python3.10/site-packages/django/views/generic/base.py", line 143, in dispatch
    return handler(request, *args, **kwargs)
  File "/home/sabbir/zenith-sys/zenith/.venv/lib/python3.10/site-packages/django/views/generic/base.py", line 226, in get
    context = self.get_context_data(**kwargs)
  File "/home/sabbir/zenith-sys/zenith/iot/views.py", line 55, in get_context_data
    "message": f"{mqtt_client.on_message()}",
TypeError: on_message() missing 3 required positional arguments: 'client', 'userdata', and 'msg'
2024-01-27 07:34:59,070 (ERROR) - django.request - Internal Server Error: /api/iot/ws/AC118/
Traceback (most recent call last):
  File "/home/sabbir/zenith-sys/zenith/.venv/lib/python3.10/site-packages/asgiref/sync.py", line 534, in thread_handler
    raise exc_info[1]
  File "/home/sabbir/zenith-sys/zenith/.venv/lib/python3.10/site-packages/django/core/handlers/exception.py", line 42, in inner
    response = await get_response(request)
  File "/home/sabbir/zenith-sys/zenith/.venv/lib/python3.10/site-packages/django/core/handlers/base.py", line 253, in _get_response_async
    response = await wrapped_callback(
  File "/home/sabbir/zenith-sys/zenith/.venv/lib/python3.10/site-packages/asgiref/sync.py", line 479, in __call__
    ret: _R = await loop.run_in_executor(
  File "/home/sabbir/zenith-sys/zenith/.venv/lib/python3.10/site-packages/asgiref/current_thread_executor.py", line 40, in run
    result = self.fn(*self.args, **self.kwargs)
  File "/home/sabbir/zenith-sys/zenith/.venv/lib/python3.10/site-packages/asgiref/sync.py", line 538, in thread_handler
    return func(*args, **kwargs)
  File "/home/sabbir/zenith-sys/zenith/.venv/lib/python3.10/site-packages/django/views/generic/base.py", line 104, in view
    return self.dispatch(request, *args, **kwargs)
  File "/home/sabbir/zenith-sys/zenith/.venv/lib/python3.10/site-packages/django/views/generic/base.py", line 143, in dispatch
    return handler(request, *args, **kwargs)
  File "/home/sabbir/zenith-sys/zenith/.venv/lib/python3.10/site-packages/django/views/generic/base.py", line 226, in get
    context = self.get_context_data(**kwargs)
  File "/home/sabbir/zenith-sys/zenith/iot/views.py", line 47, in get_context_data
    message = mqtt_client.on_message()
TypeError: on_message() missing 3 required positional arguments: 'client', 'userdata', and 'msg'
2024-01-27 07:37:57,014 (ERROR) - django.request - Internal Server Error: /api/iot/ws/AC118/
Traceback (most recent call last):
  File "/home/sabbir/zenith-sys/zenith/.venv/lib/python3.10/site-packages/asgiref/sync.py", line 534, in thread_handler
    raise exc_info[1]
  File "/home/sabbir/zenith-sys/zenith/.venv/lib/python3.10/site-packages/django/core/handlers/exception.py", line 42, in inner
    response = await get_response(request)
  File "/home/sabbir/zenith-sys/zenith/.venv/lib/python3.10/site-packages/django/core/handlers/base.py", line 253, in _get_response_async
    response = await wrapped_callback(
  File "/home/sabbir/zenith-sys/zenith/.venv/lib/python3.10/site-packages/asgiref/sync.py", line 479, in __call__
    ret: _R = await loop.run_in_executor(
  File "/home/sabbir/zenith-sys/zenith/.venv/lib/python3.10/site-packages/asgiref/current_thread_executor.py", line 40, in run
    result = self.fn(*self.args, **self.kwargs)
  File "/home/sabbir/zenith-sys/zenith/.venv/lib/python3.10/site-packages/asgiref/sync.py", line 538, in thread_handler
    return func(*args, **kwargs)
  File "/home/sabbir/zenith-sys/zenith/.venv/lib/python3.10/site-packages/django/views/generic/base.py", line 104, in view
    return self.dispatch(request, *args, **kwargs)
  File "/home/sabbir/zenith-sys/zenith/.venv/lib/python3.10/site-packages/django/views/generic/base.py", line 143, in dispatch
    return handler(request, *args, **kwargs)
  File "/home/sabbir/zenith-sys/zenith/.venv/lib/python3.10/site-packages/django/views/generic/base.py", line 226, in get
    context = self.get_context_data(**kwargs)
  File "/home/sabbir/zenith-sys/zenith/iot/views.py", line 47, in get_context_data
    message = mqtt_client.on_message()
TypeError: on_message() missing 3 required positional arguments: 'client', 'userdata', and 'msg'
2024-01-27 07:38:08,871 (ERROR) - django.request - Internal Server Error: /api/iot/ws/AC118/
Traceback (most recent call last):
  File "/home/sabbir/zenith-sys/zenith/.venv/lib/python3.10/site-packages/asgiref/sync.py", line 534, in thread_handler
    raise exc_info[1]
  File "/home/sabbir/zenith-sys/zenith/.venv/lib/python3.10/site-packages/django/core/handlers/exception.py", line 42, in inner
    response = await get_response(request)
  File "/home/sabbir/zenith-sys/zenith/.venv/lib/python3.10/site-packages/django/core/handlers/base.py", line 253, in _get_response_async
    response = await wrapped_callback(
  File "/home/sabbir/zenith-sys/zenith/.venv/lib/python3.10/site-packages/asgiref/sync.py", line 479, in __call__
    ret: _R = await loop.run_in_executor(
  File "/home/sabbir/zenith-sys/zenith/.venv/lib/python3.10/site-packages/asgiref/current_thread_executor.py", line 40, in run
    result = self.fn(*self.args, **self.kwargs)
  File "/home/sabbir/zenith-sys/zenith/.venv/lib/python3.10/site-packages/asgiref/sync.py", line 538, in thread_handler
    return func(*args, **kwargs)
  File "/home/sabbir/zenith-sys/zenith/.venv/lib/python3.10/site-packages/django/views/generic/base.py", line 104, in view
    return self.dispatch(request, *args, **kwargs)
  File "/home/sabbir/zenith-sys/zenith/.venv/lib/python3.10/site-packages/django/views/generic/base.py", line 143, in dispatch
    return handler(request, *args, **kwargs)
  File "/home/sabbir/zenith-sys/zenith/.venv/lib/python3.10/site-packages/django/views/generic/base.py", line 226, in get
    context = self.get_context_data(**kwargs)
  File "/home/sabbir/zenith-sys/zenith/iot/views.py", line 57, in get_context_data
    "message": f"{message.payload}",
AttributeError: 'function' object has no attribute 'payload'
2024-01-27 08:11:23,848 (INFO) - django.utils.autoreload - Watching for file changes with StatReloader
2024-01-27 08:11:47,680 (INFO) - django.utils.autoreload - Watching for file changes with StatReloader
2024-01-27 08:11:50,908 (WARNING) - django.request - Not Found: /ws/device/AC118/
2024-01-27 08:24:02,780 (WARNING) - django.request - Not Found: /api
2024-01-27 08:31:08,717 (ERROR) - django.request - Internal Server Error: /api/iot/ws/AC118/
Traceback (most recent call last):
  File "/home/sabbir/zenith-sys/zenith/.venv/lib/python3.10/site-packages/asgiref/sync.py", line 534, in thread_handler
    raise exc_info[1]
  File "/home/sabbir/zenith-sys/zenith/.venv/lib/python3.10/site-packages/django/core/handlers/exception.py", line 42, in inner
    response = await get_response(request)
  File "/home/sabbir/zenith-sys/zenith/.venv/lib/python3.10/site-packages/django/core/handlers/base.py", line 253, in _get_response_async
    response = await wrapped_callback(
  File "/home/sabbir/zenith-sys/zenith/.venv/lib/python3.10/site-packages/asgiref/sync.py", line 479, in __call__
    ret: _R = await loop.run_in_executor(
  File "/home/sabbir/zenith-sys/zenith/.venv/lib/python3.10/site-packages/asgiref/current_thread_executor.py", line 40, in run
    result = self.fn(*self.args, **self.kwargs)
  File "/home/sabbir/zenith-sys/zenith/.venv/lib/python3.10/site-packages/asgiref/sync.py", line 538, in thread_handler
    return func(*args, **kwargs)
  File "/home/sabbir/zenith-sys/zenith/.venv/lib/python3.10/site-packages/django/views/generic/base.py", line 104, in view
    return self.dispatch(request, *args, **kwargs)
  File "/home/sabbir/zenith-sys/zenith/.venv/lib/python3.10/site-packages/django/views/generic/base.py", line 143, in dispatch
    return handler(request, *args, **kwargs)
  File "/home/sabbir/zenith-sys/zenith/.venv/lib/python3.10/site-packages/django/views/generic/base.py", line 226, in get
    context = self.get_context_data(**kwargs)
  File "/home/sabbir/zenith-sys/zenith/iot/views.py", line 54, in get_context_data
    async_to_sync(channel_layer.group_send)(
  File "/home/sabbir/zenith-sys/zenith/.venv/lib/python3.10/site-packages/asgiref/sync.py", line 277, in __call__
    return call_result.result()
  File "/usr/lib/python3.10/concurrent/futures/_base.py", line 451, in result
    return self.__get_result()
  File "/usr/lib/python3.10/concurrent/futures/_base.py", line 403, in __get_result
    raise self._exception
  File "/home/sabbir/zenith-sys/zenith/.venv/lib/python3.10/site-packages/asgiref/sync.py", line 353, in main_wrap
    result = await self.awaitable(*args, **kwargs)
  File "/home/sabbir/zenith-sys/zenith/.venv/lib/python3.10/site-packages/channels_redis/core.py", line 539, in group_send
    ) = self._map_channel_keys_to_connection(channel_names, message)
  File "/home/sabbir/zenith-sys/zenith/.venv/lib/python3.10/site-packages/channels_redis/core.py", line 639, in _map_channel_keys_to_connection
    channel_key_to_message[key] = self.serialize(value)
  File "/home/sabbir/zenith-sys/zenith/.venv/lib/python3.10/site-packages/channels_redis/core.py", line 659, in serialize
    value = msgpack.packb(message, use_bin_type=True)
  File "/home/sabbir/zenith-sys/zenith/.venv/lib/python3.10/site-packages/msgpack/__init__.py", line 36, in packb
    return Packer(**kwargs).pack(o)
  File "msgpack/_packer.pyx", line 294, in msgpack._cmsgpack.Packer.pack
  File "msgpack/_packer.pyx", line 300, in msgpack._cmsgpack.Packer.pack
  File "msgpack/_packer.pyx", line 297, in msgpack._cmsgpack.Packer.pack
  File "msgpack/_packer.pyx", line 231, in msgpack._cmsgpack.Packer._pack
  File "msgpack/_packer.pyx", line 231, in msgpack._cmsgpack.Packer._pack
  File "msgpack/_packer.pyx", line 291, in msgpack._cmsgpack.Packer._pack
TypeError: can not serialize 'function' object
2024-01-27 09:02:43,745 (ERROR) - django.request - Internal Server Error: /api/iot/ws/AC118/
Traceback (most recent call last):
  File "/home/sabbir/zenith-sys/zenith/.venv/lib/python3.10/site-packages/asgiref/sync.py", line 534, in thread_handler
    raise exc_info[1]
  File "/home/sabbir/zenith-sys/zenith/.venv/lib/python3.10/site-packages/django/core/handlers/exception.py", line 42, in inner
    response = await get_response(request)
  File "/home/sabbir/zenith-sys/zenith/.venv/lib/python3.10/site-packages/django/core/handlers/base.py", line 253, in _get_response_async
    response = await wrapped_callback(
  File "/home/sabbir/zenith-sys/zenith/.venv/lib/python3.10/site-packages/asgiref/sync.py", line 479, in __call__
    ret: _R = await loop.run_in_executor(
  File "/home/sabbir/zenith-sys/zenith/.venv/lib/python3.10/site-packages/asgiref/current_thread_executor.py", line 40, in run
    result = self.fn(*self.args, **self.kwargs)
  File "/home/sabbir/zenith-sys/zenith/.venv/lib/python3.10/site-packages/asgiref/sync.py", line 538, in thread_handler
    return func(*args, **kwargs)
  File "/home/sabbir/zenith-sys/zenith/.venv/lib/python3.10/site-packages/django/views/generic/base.py", line 104, in view
    return self.dispatch(request, *args, **kwargs)
  File "/home/sabbir/zenith-sys/zenith/.venv/lib/python3.10/site-packages/django/views/generic/base.py", line 143, in dispatch
    return handler(request, *args, **kwargs)
  File "/home/sabbir/zenith-sys/zenith/.venv/lib/python3.10/site-packages/django/views/generic/base.py", line 226, in get
    context = self.get_context_data(**kwargs)
  File "/home/sabbir/zenith-sys/zenith/iot/views.py", line 55, in get_context_data
    async_to_sync(channel_layer.group_send)(
  File "/home/sabbir/zenith-sys/zenith/.venv/lib/python3.10/site-packages/asgiref/sync.py", line 277, in __call__
    return call_result.result()
  File "/usr/lib/python3.10/concurrent/futures/_base.py", line 451, in result
    return self.__get_result()
  File "/usr/lib/python3.10/concurrent/futures/_base.py", line 403, in __get_result
    raise self._exception
  File "/home/sabbir/zenith-sys/zenith/.venv/lib/python3.10/site-packages/asgiref/sync.py", line 353, in main_wrap
    result = await self.awaitable(*args, **kwargs)
  File "/home/sabbir/zenith-sys/zenith/.venv/lib/python3.10/site-packages/channels_redis/core.py", line 539, in group_send
    ) = self._map_channel_keys_to_connection(channel_names, message)
  File "/home/sabbir/zenith-sys/zenith/.venv/lib/python3.10/site-packages/channels_redis/core.py", line 639, in _map_channel_keys_to_connection
    channel_key_to_message[key] = self.serialize(value)
  File "/home/sabbir/zenith-sys/zenith/.venv/lib/python3.10/site-packages/channels_redis/core.py", line 659, in serialize
    value = msgpack.packb(message, use_bin_type=True)
  File "/home/sabbir/zenith-sys/zenith/.venv/lib/python3.10/site-packages/msgpack/__init__.py", line 36, in packb
    return Packer(**kwargs).pack(o)
  File "msgpack/_packer.pyx", line 294, in msgpack._cmsgpack.Packer.pack
  File "msgpack/_packer.pyx", line 300, in msgpack._cmsgpack.Packer.pack
  File "msgpack/_packer.pyx", line 297, in msgpack._cmsgpack.Packer.pack
  File "msgpack/_packer.pyx", line 231, in msgpack._cmsgpack.Packer._pack
  File "msgpack/_packer.pyx", line 231, in msgpack._cmsgpack.Packer._pack
  File "msgpack/_packer.pyx", line 291, in msgpack._cmsgpack.Packer._pack
TypeError: can not serialize 'function' object
2024-01-27 09:03:37,089 (ERROR) - django.request - Internal Server Error: /api/iot/ws/AC118/
Traceback (most recent call last):
  File "/home/sabbir/zenith-sys/zenith/.venv/lib/python3.10/site-packages/asgiref/sync.py", line 534, in thread_handler
    raise exc_info[1]
  File "/home/sabbir/zenith-sys/zenith/.venv/lib/python3.10/site-packages/django/core/handlers/exception.py", line 42, in inner
    response = await get_response(request)
  File "/home/sabbir/zenith-sys/zenith/.venv/lib/python3.10/site-packages/django/core/handlers/base.py", line 253, in _get_response_async
    response = await wrapped_callback(
  File "/home/sabbir/zenith-sys/zenith/.venv/lib/python3.10/site-packages/asgiref/sync.py", line 479, in __call__
    ret: _R = await loop.run_in_executor(
  File "/home/sabbir/zenith-sys/zenith/.venv/lib/python3.10/site-packages/asgiref/current_thread_executor.py", line 40, in run
    result = self.fn(*self.args, **self.kwargs)
  File "/home/sabbir/zenith-sys/zenith/.venv/lib/python3.10/site-packages/asgiref/sync.py", line 538, in thread_handler
    return func(*args, **kwargs)
  File "/home/sabbir/zenith-sys/zenith/.venv/lib/python3.10/site-packages/django/views/generic/base.py", line 104, in view
    return self.dispatch(request, *args, **kwargs)
  File "/home/sabbir/zenith-sys/zenith/.venv/lib/python3.10/site-packages/django/views/generic/base.py", line 143, in dispatch
    return handler(request, *args, **kwargs)
  File "/home/sabbir/zenith-sys/zenith/.venv/lib/python3.10/site-packages/django/views/generic/base.py", line 226, in get
    context = self.get_context_data(**kwargs)
  File "/home/sabbir/zenith-sys/zenith/iot/views.py", line 55, in get_context_data
    async_to_sync(channel_layer.group_send)(
  File "/home/sabbir/zenith-sys/zenith/.venv/lib/python3.10/site-packages/asgiref/sync.py", line 277, in __call__
    return call_result.result()
  File "/usr/lib/python3.10/concurrent/futures/_base.py", line 451, in result
    return self.__get_result()
  File "/usr/lib/python3.10/concurrent/futures/_base.py", line 403, in __get_result
    raise self._exception
  File "/home/sabbir/zenith-sys/zenith/.venv/lib/python3.10/site-packages/asgiref/sync.py", line 353, in main_wrap
    result = await self.awaitable(*args, **kwargs)
  File "/home/sabbir/zenith-sys/zenith/.venv/lib/python3.10/site-packages/channels_redis/core.py", line 539, in group_send
    ) = self._map_channel_keys_to_connection(channel_names, message)
  File "/home/sabbir/zenith-sys/zenith/.venv/lib/python3.10/site-packages/channels_redis/core.py", line 639, in _map_channel_keys_to_connection
    channel_key_to_message[key] = self.serialize(value)
  File "/home/sabbir/zenith-sys/zenith/.venv/lib/python3.10/site-packages/channels_redis/core.py", line 659, in serialize
    value = msgpack.packb(message, use_bin_type=True)
  File "/home/sabbir/zenith-sys/zenith/.venv/lib/python3.10/site-packages/msgpack/__init__.py", line 36, in packb
    return Packer(**kwargs).pack(o)
  File "msgpack/_packer.pyx", line 294, in msgpack._cmsgpack.Packer.pack
  File "msgpack/_packer.pyx", line 300, in msgpack._cmsgpack.Packer.pack
  File "msgpack/_packer.pyx", line 297, in msgpack._cmsgpack.Packer.pack
  File "msgpack/_packer.pyx", line 231, in msgpack._cmsgpack.Packer._pack
  File "msgpack/_packer.pyx", line 231, in msgpack._cmsgpack.Packer._pack
  File "msgpack/_packer.pyx", line 291, in msgpack._cmsgpack.Packer._pack
TypeError: can not serialize 'function' object
2024-01-27 09:04:35,154 (ERROR) - django.request - Internal Server Error: /api/iot/ws/AC118/
Traceback (most recent call last):
  File "/home/sabbir/zenith-sys/zenith/.venv/lib/python3.10/site-packages/asgiref/sync.py", line 534, in thread_handler
    raise exc_info[1]
  File "/home/sabbir/zenith-sys/zenith/.venv/lib/python3.10/site-packages/django/core/handlers/exception.py", line 42, in inner
    response = await get_response(request)
  File "/home/sabbir/zenith-sys/zenith/.venv/lib/python3.10/site-packages/django/core/handlers/base.py", line 253, in _get_response_async
    response = await wrapped_callback(
  File "/home/sabbir/zenith-sys/zenith/.venv/lib/python3.10/site-packages/asgiref/sync.py", line 479, in __call__
    ret: _R = await loop.run_in_executor(
  File "/home/sabbir/zenith-sys/zenith/.venv/lib/python3.10/site-packages/asgiref/current_thread_executor.py", line 40, in run
    result = self.fn(*self.args, **self.kwargs)
  File "/home/sabbir/zenith-sys/zenith/.venv/lib/python3.10/site-packages/asgiref/sync.py", line 538, in thread_handler
    return func(*args, **kwargs)
  File "/home/sabbir/zenith-sys/zenith/.venv/lib/python3.10/site-packages/django/views/generic/base.py", line 104, in view
    return self.dispatch(request, *args, **kwargs)
  File "/home/sabbir/zenith-sys/zenith/.venv/lib/python3.10/site-packages/django/views/generic/base.py", line 143, in dispatch
    return handler(request, *args, **kwargs)
  File "/home/sabbir/zenith-sys/zenith/.venv/lib/python3.10/site-packages/django/views/generic/base.py", line 226, in get
    context = self.get_context_data(**kwargs)
  File "/home/sabbir/zenith-sys/zenith/iot/views.py", line 61, in get_context_data
    "payload": client.on_message(),
TypeError: on_message() missing 3 required positional arguments: 'client', 'userdata', and 'msg'
2024-01-27 09:06:07,799 (ERROR) - django.request - Internal Server Error: /api/iot/ws/AC118/
Traceback (most recent call last):
  File "/home/sabbir/zenith-sys/zenith/.venv/lib/python3.10/site-packages/asgiref/sync.py", line 534, in thread_handler
    raise exc_info[1]
  File "/home/sabbir/zenith-sys/zenith/.venv/lib/python3.10/site-packages/django/core/handlers/exception.py", line 42, in inner
    response = await get_response(request)
  File "/home/sabbir/zenith-sys/zenith/.venv/lib/python3.10/site-packages/django/core/handlers/base.py", line 253, in _get_response_async
    response = await wrapped_callback(
  File "/home/sabbir/zenith-sys/zenith/.venv/lib/python3.10/site-packages/asgiref/sync.py", line 479, in __call__
    ret: _R = await loop.run_in_executor(
  File "/home/sabbir/zenith-sys/zenith/.venv/lib/python3.10/site-packages/asgiref/current_thread_executor.py", line 40, in run
    result = self.fn(*self.args, **self.kwargs)
  File "/home/sabbir/zenith-sys/zenith/.venv/lib/python3.10/site-packages/asgiref/sync.py", line 538, in thread_handler
    return func(*args, **kwargs)
  File "/home/sabbir/zenith-sys/zenith/.venv/lib/python3.10/site-packages/django/views/generic/base.py", line 104, in view
    return self.dispatch(request, *args, **kwargs)
  File "/home/sabbir/zenith-sys/zenith/.venv/lib/python3.10/site-packages/django/views/generic/base.py", line 143, in dispatch
    return handler(request, *args, **kwargs)
  File "/home/sabbir/zenith-sys/zenith/.venv/lib/python3.10/site-packages/django/views/generic/base.py", line 226, in get
    context = self.get_context_data(**kwargs)
  File "/home/sabbir/zenith-sys/zenith/iot/views.py", line 51, in get_context_data
    async_to_sync(channel_layer.group_send)(
  File "/home/sabbir/zenith-sys/zenith/.venv/lib/python3.10/site-packages/asgiref/sync.py", line 277, in __call__
    return call_result.result()
  File "/usr/lib/python3.10/concurrent/futures/_base.py", line 451, in result
    return self.__get_result()
  File "/usr/lib/python3.10/concurrent/futures/_base.py", line 403, in __get_result
    raise self._exception
  File "/home/sabbir/zenith-sys/zenith/.venv/lib/python3.10/site-packages/asgiref/sync.py", line 353, in main_wrap
    result = await self.awaitable(*args, **kwargs)
  File "/home/sabbir/zenith-sys/zenith/.venv/lib/python3.10/site-packages/channels_redis/core.py", line 539, in group_send
    ) = self._map_channel_keys_to_connection(channel_names, message)
  File "/home/sabbir/zenith-sys/zenith/.venv/lib/python3.10/site-packages/channels_redis/core.py", line 639, in _map_channel_keys_to_connection
    channel_key_to_message[key] = self.serialize(value)
  File "/home/sabbir/zenith-sys/zenith/.venv/lib/python3.10/site-packages/channels_redis/core.py", line 659, in serialize
    value = msgpack.packb(message, use_bin_type=True)
  File "/home/sabbir/zenith-sys/zenith/.venv/lib/python3.10/site-packages/msgpack/__init__.py", line 36, in packb
    return Packer(**kwargs).pack(o)
  File "msgpack/_packer.pyx", line 294, in msgpack._cmsgpack.Packer.pack
  File "msgpack/_packer.pyx", line 300, in msgpack._cmsgpack.Packer.pack
  File "msgpack/_packer.pyx", line 297, in msgpack._cmsgpack.Packer.pack
  File "msgpack/_packer.pyx", line 231, in msgpack._cmsgpack.Packer._pack
  File "msgpack/_packer.pyx", line 231, in msgpack._cmsgpack.Packer._pack
  File "msgpack/_packer.pyx", line 291, in msgpack._cmsgpack.Packer._pack
TypeError: can not serialize 'function' object
2024-01-27 09:07:26,065 (ERROR) - django.request - Internal Server Error: /api/iot/ws/AC118/
Traceback (most recent call last):
  File "/home/sabbir/zenith-sys/zenith/.venv/lib/python3.10/site-packages/asgiref/sync.py", line 534, in thread_handler
    raise exc_info[1]
  File "/home/sabbir/zenith-sys/zenith/.venv/lib/python3.10/site-packages/django/core/handlers/exception.py", line 42, in inner
    response = await get_response(request)
  File "/home/sabbir/zenith-sys/zenith/.venv/lib/python3.10/site-packages/django/core/handlers/base.py", line 253, in _get_response_async
    response = await wrapped_callback(
  File "/home/sabbir/zenith-sys/zenith/.venv/lib/python3.10/site-packages/asgiref/sync.py", line 479, in __call__
    ret: _R = await loop.run_in_executor(
  File "/home/sabbir/zenith-sys/zenith/.venv/lib/python3.10/site-packages/asgiref/current_thread_executor.py", line 40, in run
    result = self.fn(*self.args, **self.kwargs)
  File "/home/sabbir/zenith-sys/zenith/.venv/lib/python3.10/site-packages/asgiref/sync.py", line 538, in thread_handler
    return func(*args, **kwargs)
  File "/home/sabbir/zenith-sys/zenith/.venv/lib/python3.10/site-packages/django/views/generic/base.py", line 104, in view
    return self.dispatch(request, *args, **kwargs)
  File "/home/sabbir/zenith-sys/zenith/.venv/lib/python3.10/site-packages/django/views/generic/base.py", line 143, in dispatch
    return handler(request, *args, **kwargs)
  File "/home/sabbir/zenith-sys/zenith/.venv/lib/python3.10/site-packages/django/views/generic/base.py", line 226, in get
    context = self.get_context_data(**kwargs)
  File "/home/sabbir/zenith-sys/zenith/iot/views.py", line 51, in get_context_data
    async_to_sync(channel_layer.group_send)(
  File "/home/sabbir/zenith-sys/zenith/.venv/lib/python3.10/site-packages/asgiref/sync.py", line 277, in __call__
    return call_result.result()
  File "/usr/lib/python3.10/concurrent/futures/_base.py", line 451, in result
    return self.__get_result()
  File "/usr/lib/python3.10/concurrent/futures/_base.py", line 403, in __get_result
    raise self._exception
  File "/home/sabbir/zenith-sys/zenith/.venv/lib/python3.10/site-packages/asgiref/sync.py", line 353, in main_wrap
    result = await self.awaitable(*args, **kwargs)
  File "/home/sabbir/zenith-sys/zenith/.venv/lib/python3.10/site-packages/channels_redis/core.py", line 539, in group_send
    ) = self._map_channel_keys_to_connection(channel_names, message)
  File "/home/sabbir/zenith-sys/zenith/.venv/lib/python3.10/site-packages/channels_redis/core.py", line 639, in _map_channel_keys_to_connection
    channel_key_to_message[key] = self.serialize(value)
  File "/home/sabbir/zenith-sys/zenith/.venv/lib/python3.10/site-packages/channels_redis/core.py", line 659, in serialize
    value = msgpack.packb(message, use_bin_type=True)
  File "/home/sabbir/zenith-sys/zenith/.venv/lib/python3.10/site-packages/msgpack/__init__.py", line 36, in packb
    return Packer(**kwargs).pack(o)
  File "msgpack/_packer.pyx", line 294, in msgpack._cmsgpack.Packer.pack
  File "msgpack/_packer.pyx", line 300, in msgpack._cmsgpack.Packer.pack
  File "msgpack/_packer.pyx", line 297, in msgpack._cmsgpack.Packer.pack
  File "msgpack/_packer.pyx", line 231, in msgpack._cmsgpack.Packer._pack
  File "msgpack/_packer.pyx", line 231, in msgpack._cmsgpack.Packer._pack
  File "msgpack/_packer.pyx", line 291, in msgpack._cmsgpack.Packer._pack
TypeError: can not serialize 'function' object
2024-01-27 09:08:39,916 (ERROR) - django.request - Internal Server Error: /api/iot/ws/AC118/
Traceback (most recent call last):
  File "/home/sabbir/zenith-sys/zenith/.venv/lib/python3.10/site-packages/asgiref/sync.py", line 534, in thread_handler
    raise exc_info[1]
  File "/home/sabbir/zenith-sys/zenith/.venv/lib/python3.10/site-packages/django/core/handlers/exception.py", line 42, in inner
    response = await get_response(request)
  File "/home/sabbir/zenith-sys/zenith/.venv/lib/python3.10/site-packages/django/core/handlers/base.py", line 253, in _get_response_async
    response = await wrapped_callback(
  File "/home/sabbir/zenith-sys/zenith/.venv/lib/python3.10/site-packages/asgiref/sync.py", line 479, in __call__
    ret: _R = await loop.run_in_executor(
  File "/home/sabbir/zenith-sys/zenith/.venv/lib/python3.10/site-packages/asgiref/current_thread_executor.py", line 40, in run
    result = self.fn(*self.args, **self.kwargs)
  File "/home/sabbir/zenith-sys/zenith/.venv/lib/python3.10/site-packages/asgiref/sync.py", line 538, in thread_handler
    return func(*args, **kwargs)
  File "/home/sabbir/zenith-sys/zenith/.venv/lib/python3.10/site-packages/django/views/generic/base.py", line 104, in view
    return self.dispatch(request, *args, **kwargs)
  File "/home/sabbir/zenith-sys/zenith/.venv/lib/python3.10/site-packages/django/views/generic/base.py", line 143, in dispatch
    return handler(request, *args, **kwargs)
  File "/home/sabbir/zenith-sys/zenith/.venv/lib/python3.10/site-packages/django/views/generic/base.py", line 226, in get
    context = self.get_context_data(**kwargs)
  File "/home/sabbir/zenith-sys/zenith/iot/views.py", line 51, in get_context_data
    async_to_sync(channel_layer.group_send)(
  File "/home/sabbir/zenith-sys/zenith/.venv/lib/python3.10/site-packages/asgiref/sync.py", line 277, in __call__
    return call_result.result()
  File "/usr/lib/python3.10/concurrent/futures/_base.py", line 451, in result
    return self.__get_result()
  File "/usr/lib/python3.10/concurrent/futures/_base.py", line 403, in __get_result
    raise self._exception
  File "/home/sabbir/zenith-sys/zenith/.venv/lib/python3.10/site-packages/asgiref/sync.py", line 353, in main_wrap
    result = await self.awaitable(*args, **kwargs)
  File "/home/sabbir/zenith-sys/zenith/.venv/lib/python3.10/site-packages/channels_redis/core.py", line 539, in group_send
    ) = self._map_channel_keys_to_connection(channel_names, message)
  File "/home/sabbir/zenith-sys/zenith/.venv/lib/python3.10/site-packages/channels_redis/core.py", line 639, in _map_channel_keys_to_connection
    channel_key_to_message[key] = self.serialize(value)
  File "/home/sabbir/zenith-sys/zenith/.venv/lib/python3.10/site-packages/channels_redis/core.py", line 659, in serialize
    value = msgpack.packb(message, use_bin_type=True)
  File "/home/sabbir/zenith-sys/zenith/.venv/lib/python3.10/site-packages/msgpack/__init__.py", line 36, in packb
    return Packer(**kwargs).pack(o)
  File "msgpack/_packer.pyx", line 294, in msgpack._cmsgpack.Packer.pack
  File "msgpack/_packer.pyx", line 300, in msgpack._cmsgpack.Packer.pack
  File "msgpack/_packer.pyx", line 297, in msgpack._cmsgpack.Packer.pack
  File "msgpack/_packer.pyx", line 231, in msgpack._cmsgpack.Packer._pack
  File "msgpack/_packer.pyx", line 231, in msgpack._cmsgpack.Packer._pack
  File "msgpack/_packer.pyx", line 291, in msgpack._cmsgpack.Packer._pack
TypeError: can not serialize 'function' object
2024-01-27 09:09:35,483 (ERROR) - django.request - Internal Server Error: /api/iot/ws/AC118/
Traceback (most recent call last):
  File "/home/sabbir/zenith-sys/zenith/.venv/lib/python3.10/site-packages/asgiref/sync.py", line 534, in thread_handler
    raise exc_info[1]
  File "/home/sabbir/zenith-sys/zenith/.venv/lib/python3.10/site-packages/django/core/handlers/exception.py", line 42, in inner
    response = await get_response(request)
  File "/home/sabbir/zenith-sys/zenith/.venv/lib/python3.10/site-packages/django/core/handlers/base.py", line 253, in _get_response_async
    response = await wrapped_callback(
  File "/home/sabbir/zenith-sys/zenith/.venv/lib/python3.10/site-packages/asgiref/sync.py", line 479, in __call__
    ret: _R = await loop.run_in_executor(
  File "/home/sabbir/zenith-sys/zenith/.venv/lib/python3.10/site-packages/asgiref/current_thread_executor.py", line 40, in run
    result = self.fn(*self.args, **self.kwargs)
  File "/home/sabbir/zenith-sys/zenith/.venv/lib/python3.10/site-packages/asgiref/sync.py", line 538, in thread_handler
    return func(*args, **kwargs)
  File "/home/sabbir/zenith-sys/zenith/.venv/lib/python3.10/site-packages/django/views/generic/base.py", line 104, in view
    return self.dispatch(request, *args, **kwargs)
  File "/home/sabbir/zenith-sys/zenith/.venv/lib/python3.10/site-packages/django/views/generic/base.py", line 143, in dispatch
    return handler(request, *args, **kwargs)
  File "/home/sabbir/zenith-sys/zenith/.venv/lib/python3.10/site-packages/django/views/generic/base.py", line 226, in get
    context = self.get_context_data(**kwargs)
  File "/home/sabbir/zenith-sys/zenith/iot/views.py", line 47, in get_context_data
    topic, payload = client.on_message
TypeError: cannot unpack non-iterable function object
2024-01-27 09:11:37,145 (ERROR) - django.request - Internal Server Error: /api/iot/ws/AC118/
Traceback (most recent call last):
  File "/home/sabbir/zenith-sys/zenith/.venv/lib/python3.10/site-packages/asgiref/sync.py", line 534, in thread_handler
    raise exc_info[1]
  File "/home/sabbir/zenith-sys/zenith/.venv/lib/python3.10/site-packages/django/core/handlers/exception.py", line 42, in inner
    response = await get_response(request)
  File "/home/sabbir/zenith-sys/zenith/.venv/lib/python3.10/site-packages/django/core/handlers/base.py", line 253, in _get_response_async
    response = await wrapped_callback(
  File "/home/sabbir/zenith-sys/zenith/.venv/lib/python3.10/site-packages/asgiref/sync.py", line 479, in __call__
    ret: _R = await loop.run_in_executor(
  File "/home/sabbir/zenith-sys/zenith/.venv/lib/python3.10/site-packages/asgiref/current_thread_executor.py", line 40, in run
    result = self.fn(*self.args, **self.kwargs)
  File "/home/sabbir/zenith-sys/zenith/.venv/lib/python3.10/site-packages/asgiref/sync.py", line 538, in thread_handler
    return func(*args, **kwargs)
  File "/home/sabbir/zenith-sys/zenith/.venv/lib/python3.10/site-packages/django/views/generic/base.py", line 104, in view
    return self.dispatch(request, *args, **kwargs)
  File "/home/sabbir/zenith-sys/zenith/.venv/lib/python3.10/site-packages/django/views/generic/base.py", line 143, in dispatch
    return handler(request, *args, **kwargs)
  File "/home/sabbir/zenith-sys/zenith/.venv/lib/python3.10/site-packages/django/views/generic/base.py", line 226, in get
    context = self.get_context_data(**kwargs)
  File "/home/sabbir/zenith-sys/zenith/iot/views.py", line 47, in get_context_data
    topic, payload = client.on_message
TypeError: cannot unpack non-iterable function object
2024-01-27 09:11:56,653 (ERROR) - django.request - Internal Server Error: /api/iot/ws/AC118/
Traceback (most recent call last):
  File "/home/sabbir/zenith-sys/zenith/.venv/lib/python3.10/site-packages/asgiref/sync.py", line 534, in thread_handler
    raise exc_info[1]
  File "/home/sabbir/zenith-sys/zenith/.venv/lib/python3.10/site-packages/django/core/handlers/exception.py", line 42, in inner
    response = await get_response(request)
  File "/home/sabbir/zenith-sys/zenith/.venv/lib/python3.10/site-packages/django/core/handlers/base.py", line 253, in _get_response_async
    response = await wrapped_callback(
  File "/home/sabbir/zenith-sys/zenith/.venv/lib/python3.10/site-packages/asgiref/sync.py", line 479, in __call__
    ret: _R = await loop.run_in_executor(
  File "/home/sabbir/zenith-sys/zenith/.venv/lib/python3.10/site-packages/asgiref/current_thread_executor.py", line 40, in run
    result = self.fn(*self.args, **self.kwargs)
  File "/home/sabbir/zenith-sys/zenith/.venv/lib/python3.10/site-packages/asgiref/sync.py", line 538, in thread_handler
    return func(*args, **kwargs)
  File "/home/sabbir/zenith-sys/zenith/.venv/lib/python3.10/site-packages/django/views/generic/base.py", line 104, in view
    return self.dispatch(request, *args, **kwargs)
  File "/home/sabbir/zenith-sys/zenith/.venv/lib/python3.10/site-packages/django/views/generic/base.py", line 143, in dispatch
    return handler(request, *args, **kwargs)
  File "/home/sabbir/zenith-sys/zenith/.venv/lib/python3.10/site-packages/django/views/generic/base.py", line 226, in get
    context = self.get_context_data(**kwargs)
  File "/home/sabbir/zenith-sys/zenith/iot/views.py", line 53, in get_context_data
    async_to_sync(channel_layer.group_send)(
  File "/home/sabbir/zenith-sys/zenith/.venv/lib/python3.10/site-packages/asgiref/sync.py", line 277, in __call__
    return call_result.result()
  File "/usr/lib/python3.10/concurrent/futures/_base.py", line 451, in result
    return self.__get_result()
  File "/usr/lib/python3.10/concurrent/futures/_base.py", line 403, in __get_result
    raise self._exception
  File "/home/sabbir/zenith-sys/zenith/.venv/lib/python3.10/site-packages/asgiref/sync.py", line 353, in main_wrap
    result = await self.awaitable(*args, **kwargs)
  File "/home/sabbir/zenith-sys/zenith/.venv/lib/python3.10/site-packages/channels_redis/core.py", line 539, in group_send
    ) = self._map_channel_keys_to_connection(channel_names, message)
  File "/home/sabbir/zenith-sys/zenith/.venv/lib/python3.10/site-packages/channels_redis/core.py", line 639, in _map_channel_keys_to_connection
    channel_key_to_message[key] = self.serialize(value)
  File "/home/sabbir/zenith-sys/zenith/.venv/lib/python3.10/site-packages/channels_redis/core.py", line 659, in serialize
    value = msgpack.packb(message, use_bin_type=True)
  File "/home/sabbir/zenith-sys/zenith/.venv/lib/python3.10/site-packages/msgpack/__init__.py", line 36, in packb
    return Packer(**kwargs).pack(o)
  File "msgpack/_packer.pyx", line 294, in msgpack._cmsgpack.Packer.pack
  File "msgpack/_packer.pyx", line 300, in msgpack._cmsgpack.Packer.pack
  File "msgpack/_packer.pyx", line 297, in msgpack._cmsgpack.Packer.pack
  File "msgpack/_packer.pyx", line 231, in msgpack._cmsgpack.Packer._pack
  File "msgpack/_packer.pyx", line 231, in msgpack._cmsgpack.Packer._pack
  File "msgpack/_packer.pyx", line 291, in msgpack._cmsgpack.Packer._pack
TypeError: can not serialize 'function' object
2024-01-27 09:15:07,687 (ERROR) - django.request - Internal Server Error: /api/iot/ws/AC118/
Traceback (most recent call last):
  File "/home/sabbir/zenith-sys/zenith/.venv/lib/python3.10/site-packages/asgiref/sync.py", line 534, in thread_handler
    raise exc_info[1]
  File "/home/sabbir/zenith-sys/zenith/.venv/lib/python3.10/site-packages/django/core/handlers/exception.py", line 42, in inner
    response = await get_response(request)
  File "/home/sabbir/zenith-sys/zenith/.venv/lib/python3.10/site-packages/django/core/handlers/base.py", line 253, in _get_response_async
    response = await wrapped_callback(
  File "/home/sabbir/zenith-sys/zenith/.venv/lib/python3.10/site-packages/asgiref/sync.py", line 479, in __call__
    ret: _R = await loop.run_in_executor(
  File "/home/sabbir/zenith-sys/zenith/.venv/lib/python3.10/site-packages/asgiref/current_thread_executor.py", line 40, in run
    result = self.fn(*self.args, **self.kwargs)
  File "/home/sabbir/zenith-sys/zenith/.venv/lib/python3.10/site-packages/asgiref/sync.py", line 538, in thread_handler
    return func(*args, **kwargs)
  File "/home/sabbir/zenith-sys/zenith/.venv/lib/python3.10/site-packages/django/views/generic/base.py", line 104, in view
    return self.dispatch(request, *args, **kwargs)
  File "/home/sabbir/zenith-sys/zenith/.venv/lib/python3.10/site-packages/django/views/generic/base.py", line 143, in dispatch
    return handler(request, *args, **kwargs)
  File "/home/sabbir/zenith-sys/zenith/.venv/lib/python3.10/site-packages/django/views/generic/base.py", line 226, in get
    context = self.get_context_data(**kwargs)
  File "/home/sabbir/zenith-sys/zenith/iot/views.py", line 53, in get_context_data
    async_to_sync(channel_layer.group_send)(
  File "/home/sabbir/zenith-sys/zenith/.venv/lib/python3.10/site-packages/asgiref/sync.py", line 277, in __call__
    return call_result.result()
  File "/usr/lib/python3.10/concurrent/futures/_base.py", line 451, in result
    return self.__get_result()
  File "/usr/lib/python3.10/concurrent/futures/_base.py", line 403, in __get_result
    raise self._exception
  File "/home/sabbir/zenith-sys/zenith/.venv/lib/python3.10/site-packages/asgiref/sync.py", line 353, in main_wrap
    result = await self.awaitable(*args, **kwargs)
  File "/home/sabbir/zenith-sys/zenith/.venv/lib/python3.10/site-packages/channels_redis/core.py", line 539, in group_send
    ) = self._map_channel_keys_to_connection(channel_names, message)
  File "/home/sabbir/zenith-sys/zenith/.venv/lib/python3.10/site-packages/channels_redis/core.py", line 639, in _map_channel_keys_to_connection
    channel_key_to_message[key] = self.serialize(value)
  File "/home/sabbir/zenith-sys/zenith/.venv/lib/python3.10/site-packages/channels_redis/core.py", line 659, in serialize
    value = msgpack.packb(message, use_bin_type=True)
  File "/home/sabbir/zenith-sys/zenith/.venv/lib/python3.10/site-packages/msgpack/__init__.py", line 36, in packb
    return Packer(**kwargs).pack(o)
  File "msgpack/_packer.pyx", line 294, in msgpack._cmsgpack.Packer.pack
  File "msgpack/_packer.pyx", line 300, in msgpack._cmsgpack.Packer.pack
  File "msgpack/_packer.pyx", line 297, in msgpack._cmsgpack.Packer.pack
  File "msgpack/_packer.pyx", line 231, in msgpack._cmsgpack.Packer._pack
  File "msgpack/_packer.pyx", line 291, in msgpack._cmsgpack.Packer._pack
TypeError: can not serialize 'set' object
2024-01-27 09:15:30,097 (ERROR) - django.request - Internal Server Error: /api/iot/ws/AC118/
Traceback (most recent call last):
  File "/home/sabbir/zenith-sys/zenith/.venv/lib/python3.10/site-packages/asgiref/sync.py", line 534, in thread_handler
    raise exc_info[1]
  File "/home/sabbir/zenith-sys/zenith/.venv/lib/python3.10/site-packages/django/core/handlers/exception.py", line 42, in inner
    response = await get_response(request)
  File "/home/sabbir/zenith-sys/zenith/.venv/lib/python3.10/site-packages/django/core/handlers/base.py", line 253, in _get_response_async
    response = await wrapped_callback(
  File "/home/sabbir/zenith-sys/zenith/.venv/lib/python3.10/site-packages/asgiref/sync.py", line 479, in __call__
    ret: _R = await loop.run_in_executor(
  File "/home/sabbir/zenith-sys/zenith/.venv/lib/python3.10/site-packages/asgiref/current_thread_executor.py", line 40, in run
    result = self.fn(*self.args, **self.kwargs)
  File "/home/sabbir/zenith-sys/zenith/.venv/lib/python3.10/site-packages/asgiref/sync.py", line 538, in thread_handler
    return func(*args, **kwargs)
  File "/home/sabbir/zenith-sys/zenith/.venv/lib/python3.10/site-packages/django/views/generic/base.py", line 104, in view
    return self.dispatch(request, *args, **kwargs)
  File "/home/sabbir/zenith-sys/zenith/.venv/lib/python3.10/site-packages/django/views/generic/base.py", line 143, in dispatch
    return handler(request, *args, **kwargs)
  File "/home/sabbir/zenith-sys/zenith/.venv/lib/python3.10/site-packages/django/views/generic/base.py", line 226, in get
    context = self.get_context_data(**kwargs)
  File "/home/sabbir/zenith-sys/zenith/iot/views.py", line 53, in get_context_data
    async_to_sync(channel_layer.group_send)(
  File "/home/sabbir/zenith-sys/zenith/.venv/lib/python3.10/site-packages/asgiref/sync.py", line 277, in __call__
    return call_result.result()
  File "/usr/lib/python3.10/concurrent/futures/_base.py", line 451, in result
    return self.__get_result()
  File "/usr/lib/python3.10/concurrent/futures/_base.py", line 403, in __get_result
    raise self._exception
  File "/home/sabbir/zenith-sys/zenith/.venv/lib/python3.10/site-packages/asgiref/sync.py", line 353, in main_wrap
    result = await self.awaitable(*args, **kwargs)
  File "/home/sabbir/zenith-sys/zenith/.venv/lib/python3.10/site-packages/channels_redis/core.py", line 539, in group_send
    ) = self._map_channel_keys_to_connection(channel_names, message)
  File "/home/sabbir/zenith-sys/zenith/.venv/lib/python3.10/site-packages/channels_redis/core.py", line 639, in _map_channel_keys_to_connection
    channel_key_to_message[key] = self.serialize(value)
  File "/home/sabbir/zenith-sys/zenith/.venv/lib/python3.10/site-packages/channels_redis/core.py", line 659, in serialize
    value = msgpack.packb(message, use_bin_type=True)
  File "/home/sabbir/zenith-sys/zenith/.venv/lib/python3.10/site-packages/msgpack/__init__.py", line 36, in packb
    return Packer(**kwargs).pack(o)
  File "msgpack/_packer.pyx", line 294, in msgpack._cmsgpack.Packer.pack
  File "msgpack/_packer.pyx", line 300, in msgpack._cmsgpack.Packer.pack
  File "msgpack/_packer.pyx", line 297, in msgpack._cmsgpack.Packer.pack
  File "msgpack/_packer.pyx", line 231, in msgpack._cmsgpack.Packer._pack
  File "msgpack/_packer.pyx", line 291, in msgpack._cmsgpack.Packer._pack
TypeError: can not serialize 'set' object
2024-01-27 09:15:49,078 (ERROR) - django.request - Internal Server Error: /api/iot/ws/AC118/
Traceback (most recent call last):
  File "/home/sabbir/zenith-sys/zenith/.venv/lib/python3.10/site-packages/asgiref/sync.py", line 534, in thread_handler
    raise exc_info[1]
  File "/home/sabbir/zenith-sys/zenith/.venv/lib/python3.10/site-packages/django/core/handlers/exception.py", line 42, in inner
    response = await get_response(request)
  File "/home/sabbir/zenith-sys/zenith/.venv/lib/python3.10/site-packages/django/core/handlers/base.py", line 253, in _get_response_async
    response = await wrapped_callback(
  File "/home/sabbir/zenith-sys/zenith/.venv/lib/python3.10/site-packages/asgiref/sync.py", line 479, in __call__
    ret: _R = await loop.run_in_executor(
  File "/home/sabbir/zenith-sys/zenith/.venv/lib/python3.10/site-packages/asgiref/current_thread_executor.py", line 40, in run
    result = self.fn(*self.args, **self.kwargs)
  File "/home/sabbir/zenith-sys/zenith/.venv/lib/python3.10/site-packages/asgiref/sync.py", line 538, in thread_handler
    return func(*args, **kwargs)
  File "/home/sabbir/zenith-sys/zenith/.venv/lib/python3.10/site-packages/django/views/generic/base.py", line 104, in view
    return self.dispatch(request, *args, **kwargs)
  File "/home/sabbir/zenith-sys/zenith/.venv/lib/python3.10/site-packages/django/views/generic/base.py", line 143, in dispatch
    return handler(request, *args, **kwargs)
  File "/home/sabbir/zenith-sys/zenith/.venv/lib/python3.10/site-packages/django/views/generic/base.py", line 226, in get
    context = self.get_context_data(**kwargs)
  File "/home/sabbir/zenith-sys/zenith/iot/views.py", line 53, in get_context_data
    async_to_sync(channel_layer.group_send)(
  File "/home/sabbir/zenith-sys/zenith/.venv/lib/python3.10/site-packages/asgiref/sync.py", line 277, in __call__
    return call_result.result()
  File "/usr/lib/python3.10/concurrent/futures/_base.py", line 451, in result
    return self.__get_result()
  File "/usr/lib/python3.10/concurrent/futures/_base.py", line 403, in __get_result
    raise self._exception
  File "/home/sabbir/zenith-sys/zenith/.venv/lib/python3.10/site-packages/asgiref/sync.py", line 353, in main_wrap
    result = await self.awaitable(*args, **kwargs)
  File "/home/sabbir/zenith-sys/zenith/.venv/lib/python3.10/site-packages/channels_redis/core.py", line 539, in group_send
    ) = self._map_channel_keys_to_connection(channel_names, message)
  File "/home/sabbir/zenith-sys/zenith/.venv/lib/python3.10/site-packages/channels_redis/core.py", line 639, in _map_channel_keys_to_connection
    channel_key_to_message[key] = self.serialize(value)
  File "/home/sabbir/zenith-sys/zenith/.venv/lib/python3.10/site-packages/channels_redis/core.py", line 659, in serialize
    value = msgpack.packb(message, use_bin_type=True)
  File "/home/sabbir/zenith-sys/zenith/.venv/lib/python3.10/site-packages/msgpack/__init__.py", line 36, in packb
    return Packer(**kwargs).pack(o)
  File "msgpack/_packer.pyx", line 294, in msgpack._cmsgpack.Packer.pack
  File "msgpack/_packer.pyx", line 300, in msgpack._cmsgpack.Packer.pack
  File "msgpack/_packer.pyx", line 297, in msgpack._cmsgpack.Packer.pack
  File "msgpack/_packer.pyx", line 231, in msgpack._cmsgpack.Packer._pack
  File "msgpack/_packer.pyx", line 291, in msgpack._cmsgpack.Packer._pack
TypeError: can not serialize 'set' object
2024-01-27 09:17:44,597 (ERROR) - django.request - Internal Server Error: /api/iot/ws/AC118/
Traceback (most recent call last):
  File "/home/sabbir/zenith-sys/zenith/.venv/lib/python3.10/site-packages/asgiref/sync.py", line 534, in thread_handler
    raise exc_info[1]
  File "/home/sabbir/zenith-sys/zenith/.venv/lib/python3.10/site-packages/django/core/handlers/exception.py", line 42, in inner
    response = await get_response(request)
  File "/home/sabbir/zenith-sys/zenith/.venv/lib/python3.10/site-packages/django/core/handlers/base.py", line 253, in _get_response_async
    response = await wrapped_callback(
  File "/home/sabbir/zenith-sys/zenith/.venv/lib/python3.10/site-packages/asgiref/sync.py", line 479, in __call__
    ret: _R = await loop.run_in_executor(
  File "/home/sabbir/zenith-sys/zenith/.venv/lib/python3.10/site-packages/asgiref/current_thread_executor.py", line 40, in run
    result = self.fn(*self.args, **self.kwargs)
  File "/home/sabbir/zenith-sys/zenith/.venv/lib/python3.10/site-packages/asgiref/sync.py", line 538, in thread_handler
    return func(*args, **kwargs)
  File "/home/sabbir/zenith-sys/zenith/.venv/lib/python3.10/site-packages/django/views/generic/base.py", line 104, in view
    return self.dispatch(request, *args, **kwargs)
  File "/home/sabbir/zenith-sys/zenith/.venv/lib/python3.10/site-packages/django/views/generic/base.py", line 143, in dispatch
    return handler(request, *args, **kwargs)
  File "/home/sabbir/zenith-sys/zenith/.venv/lib/python3.10/site-packages/django/views/generic/base.py", line 226, in get
    context = self.get_context_data(**kwargs)
  File "/home/sabbir/zenith-sys/zenith/iot/views.py", line 53, in get_context_data
    async_to_sync(channel_layer.group_send)(
  File "/home/sabbir/zenith-sys/zenith/.venv/lib/python3.10/site-packages/asgiref/sync.py", line 277, in __call__
    return call_result.result()
  File "/usr/lib/python3.10/concurrent/futures/_base.py", line 451, in result
    return self.__get_result()
  File "/usr/lib/python3.10/concurrent/futures/_base.py", line 403, in __get_result
    raise self._exception
  File "/home/sabbir/zenith-sys/zenith/.venv/lib/python3.10/site-packages/asgiref/sync.py", line 353, in main_wrap
    result = await self.awaitable(*args, **kwargs)
  File "/home/sabbir/zenith-sys/zenith/.venv/lib/python3.10/site-packages/channels_redis/core.py", line 539, in group_send
    ) = self._map_channel_keys_to_connection(channel_names, message)
  File "/home/sabbir/zenith-sys/zenith/.venv/lib/python3.10/site-packages/channels_redis/core.py", line 639, in _map_channel_keys_to_connection
    channel_key_to_message[key] = self.serialize(value)
  File "/home/sabbir/zenith-sys/zenith/.venv/lib/python3.10/site-packages/channels_redis/core.py", line 659, in serialize
    value = msgpack.packb(message, use_bin_type=True)
  File "/home/sabbir/zenith-sys/zenith/.venv/lib/python3.10/site-packages/msgpack/__init__.py", line 36, in packb
    return Packer(**kwargs).pack(o)
  File "msgpack/_packer.pyx", line 294, in msgpack._cmsgpack.Packer.pack
  File "msgpack/_packer.pyx", line 300, in msgpack._cmsgpack.Packer.pack
  File "msgpack/_packer.pyx", line 297, in msgpack._cmsgpack.Packer.pack
  File "msgpack/_packer.pyx", line 231, in msgpack._cmsgpack.Packer._pack
  File "msgpack/_packer.pyx", line 291, in msgpack._cmsgpack.Packer._pack
TypeError: can not serialize 'set' object
2024-01-27 09:20:16,802 (ERROR) - django.request - Internal Server Error: /api/iot/ws/AC118/
Traceback (most recent call last):
  File "/home/sabbir/zenith-sys/zenith/.venv/lib/python3.10/site-packages/asgiref/sync.py", line 534, in thread_handler
    raise exc_info[1]
  File "/home/sabbir/zenith-sys/zenith/.venv/lib/python3.10/site-packages/django/core/handlers/exception.py", line 42, in inner
    response = await get_response(request)
  File "/home/sabbir/zenith-sys/zenith/.venv/lib/python3.10/site-packages/django/core/handlers/base.py", line 253, in _get_response_async
    response = await wrapped_callback(
  File "/home/sabbir/zenith-sys/zenith/.venv/lib/python3.10/site-packages/asgiref/sync.py", line 479, in __call__
    ret: _R = await loop.run_in_executor(
  File "/home/sabbir/zenith-sys/zenith/.venv/lib/python3.10/site-packages/asgiref/current_thread_executor.py", line 40, in run
    result = self.fn(*self.args, **self.kwargs)
  File "/home/sabbir/zenith-sys/zenith/.venv/lib/python3.10/site-packages/asgiref/sync.py", line 538, in thread_handler
    return func(*args, **kwargs)
  File "/home/sabbir/zenith-sys/zenith/.venv/lib/python3.10/site-packages/django/views/generic/base.py", line 104, in view
    return self.dispatch(request, *args, **kwargs)
  File "/home/sabbir/zenith-sys/zenith/.venv/lib/python3.10/site-packages/django/views/generic/base.py", line 143, in dispatch
    return handler(request, *args, **kwargs)
  File "/home/sabbir/zenith-sys/zenith/.venv/lib/python3.10/site-packages/django/views/generic/base.py", line 226, in get
    context = self.get_context_data(**kwargs)
  File "/home/sabbir/zenith-sys/zenith/iot/views.py", line 51, in get_context_data
    async_to_sync(channel_layer.group_send)(
  File "/home/sabbir/zenith-sys/zenith/.venv/lib/python3.10/site-packages/asgiref/sync.py", line 277, in __call__
    return call_result.result()
  File "/usr/lib/python3.10/concurrent/futures/_base.py", line 451, in result
    return self.__get_result()
  File "/usr/lib/python3.10/concurrent/futures/_base.py", line 403, in __get_result
    raise self._exception
  File "/home/sabbir/zenith-sys/zenith/.venv/lib/python3.10/site-packages/asgiref/sync.py", line 353, in main_wrap
    result = await self.awaitable(*args, **kwargs)
  File "/home/sabbir/zenith-sys/zenith/.venv/lib/python3.10/site-packages/channels_redis/core.py", line 539, in group_send
    ) = self._map_channel_keys_to_connection(channel_names, message)
  File "/home/sabbir/zenith-sys/zenith/.venv/lib/python3.10/site-packages/channels_redis/core.py", line 639, in _map_channel_keys_to_connection
    channel_key_to_message[key] = self.serialize(value)
  File "/home/sabbir/zenith-sys/zenith/.venv/lib/python3.10/site-packages/channels_redis/core.py", line 659, in serialize
    value = msgpack.packb(message, use_bin_type=True)
  File "/home/sabbir/zenith-sys/zenith/.venv/lib/python3.10/site-packages/msgpack/__init__.py", line 36, in packb
    return Packer(**kwargs).pack(o)
  File "msgpack/_packer.pyx", line 294, in msgpack._cmsgpack.Packer.pack
  File "msgpack/_packer.pyx", line 300, in msgpack._cmsgpack.Packer.pack
  File "msgpack/_packer.pyx", line 297, in msgpack._cmsgpack.Packer.pack
  File "msgpack/_packer.pyx", line 231, in msgpack._cmsgpack.Packer._pack
  File "msgpack/_packer.pyx", line 291, in msgpack._cmsgpack.Packer._pack
TypeError: can not serialize 'set' object
2024-01-27 09:22:32,679 (ERROR) - django.request - Internal Server Error: /api/iot/ws/AC118/
Traceback (most recent call last):
  File "/home/sabbir/zenith-sys/zenith/.venv/lib/python3.10/site-packages/asgiref/sync.py", line 534, in thread_handler
    raise exc_info[1]
  File "/home/sabbir/zenith-sys/zenith/.venv/lib/python3.10/site-packages/django/core/handlers/exception.py", line 42, in inner
    response = await get_response(request)
  File "/home/sabbir/zenith-sys/zenith/.venv/lib/python3.10/site-packages/django/core/handlers/base.py", line 253, in _get_response_async
    response = await wrapped_callback(
  File "/home/sabbir/zenith-sys/zenith/.venv/lib/python3.10/site-packages/asgiref/sync.py", line 479, in __call__
    ret: _R = await loop.run_in_executor(
  File "/home/sabbir/zenith-sys/zenith/.venv/lib/python3.10/site-packages/asgiref/current_thread_executor.py", line 40, in run
    result = self.fn(*self.args, **self.kwargs)
  File "/home/sabbir/zenith-sys/zenith/.venv/lib/python3.10/site-packages/asgiref/sync.py", line 538, in thread_handler
    return func(*args, **kwargs)
  File "/home/sabbir/zenith-sys/zenith/.venv/lib/python3.10/site-packages/django/views/generic/base.py", line 104, in view
    return self.dispatch(request, *args, **kwargs)
  File "/home/sabbir/zenith-sys/zenith/.venv/lib/python3.10/site-packages/django/views/generic/base.py", line 143, in dispatch
    return handler(request, *args, **kwargs)
  File "/home/sabbir/zenith-sys/zenith/.venv/lib/python3.10/site-packages/django/views/generic/base.py", line 226, in get
    context = self.get_context_data(**kwargs)
  File "/home/sabbir/zenith-sys/zenith/iot/views.py", line 46, in get_context_data
    client.on_message = self.on_message
AttributeError: 'IoTChannel' object has no attribute 'on_message'
2024-01-27 10:03:30,277 (ERROR) - django.request - Internal Server Error: /api/iot/ws/AC118/
Traceback (most recent call last):
  File "/home/sabbir/zenith-sys/zenith/.venv/lib/python3.10/site-packages/asgiref/sync.py", line 534, in thread_handler
    raise exc_info[1]
  File "/home/sabbir/zenith-sys/zenith/.venv/lib/python3.10/site-packages/django/core/handlers/exception.py", line 42, in inner
    response = await get_response(request)
  File "/home/sabbir/zenith-sys/zenith/.venv/lib/python3.10/site-packages/django/core/handlers/base.py", line 253, in _get_response_async
    response = await wrapped_callback(
  File "/home/sabbir/zenith-sys/zenith/.venv/lib/python3.10/site-packages/asgiref/sync.py", line 479, in __call__
    ret: _R = await loop.run_in_executor(
  File "/home/sabbir/zenith-sys/zenith/.venv/lib/python3.10/site-packages/asgiref/current_thread_executor.py", line 40, in run
    result = self.fn(*self.args, **self.kwargs)
  File "/home/sabbir/zenith-sys/zenith/.venv/lib/python3.10/site-packages/asgiref/sync.py", line 538, in thread_handler
    return func(*args, **kwargs)
  File "/home/sabbir/zenith-sys/zenith/.venv/lib/python3.10/site-packages/django/views/generic/base.py", line 104, in view
    return self.dispatch(request, *args, **kwargs)
  File "/home/sabbir/zenith-sys/zenith/.venv/lib/python3.10/site-packages/django/views/generic/base.py", line 143, in dispatch
    return handler(request, *args, **kwargs)
  File "/home/sabbir/zenith-sys/zenith/.venv/lib/python3.10/site-packages/django/views/generic/base.py", line 226, in get
    context = self.get_context_data(**kwargs)
  File "/home/sabbir/zenith-sys/zenith/iot/views.py", line 45, in get_context_data
    client.on_connect(lambda client, userdata, flags, rc: client.subscribe(topic))
TypeError: on_connect() missing 3 required positional arguments: 'userdata', 'flags', and 'rc'
2024-01-27 10:04:08,120 (ERROR) - django.request - Internal Server Error: /api/iot/ws/AC118/
Traceback (most recent call last):
  File "/home/sabbir/zenith-sys/zenith/.venv/lib/python3.10/site-packages/asgiref/sync.py", line 534, in thread_handler
    raise exc_info[1]
  File "/home/sabbir/zenith-sys/zenith/.venv/lib/python3.10/site-packages/django/core/handlers/exception.py", line 42, in inner
    response = await get_response(request)
  File "/home/sabbir/zenith-sys/zenith/.venv/lib/python3.10/site-packages/django/core/handlers/base.py", line 253, in _get_response_async
    response = await wrapped_callback(
  File "/home/sabbir/zenith-sys/zenith/.venv/lib/python3.10/site-packages/asgiref/sync.py", line 479, in __call__
    ret: _R = await loop.run_in_executor(
  File "/home/sabbir/zenith-sys/zenith/.venv/lib/python3.10/site-packages/asgiref/current_thread_executor.py", line 40, in run
    result = self.fn(*self.args, **self.kwargs)
  File "/home/sabbir/zenith-sys/zenith/.venv/lib/python3.10/site-packages/asgiref/sync.py", line 538, in thread_handler
    return func(*args, **kwargs)
  File "/home/sabbir/zenith-sys/zenith/.venv/lib/python3.10/site-packages/django/views/generic/base.py", line 104, in view
    return self.dispatch(request, *args, **kwargs)
  File "/home/sabbir/zenith-sys/zenith/.venv/lib/python3.10/site-packages/django/views/generic/base.py", line 143, in dispatch
    return handler(request, *args, **kwargs)
  File "/home/sabbir/zenith-sys/zenith/.venv/lib/python3.10/site-packages/django/views/generic/base.py", line 226, in get
    context = self.get_context_data(**kwargs)
  File "/home/sabbir/zenith-sys/zenith/iot/views.py", line 45, in get_context_data
    client.on_connect(
TypeError: on_connect() missing 3 required positional arguments: 'userdata', 'flags', and 'rc'
2024-01-27 10:16:33,871 (WARNING) - django.request - Not Found: /api/iot/ws/
2024-01-28 19:21:29,655 (INFO) - django.utils.autoreload - Watching for file changes with StatReloader
2024-01-28 19:22:09,595 (WARNING) - django.request - Not Found: /ws/notifications/
2024-01-29 11:57:58,495 (WARNING) - django.request - Not Found: /api/iot/ws/
2024-01-29 11:57:58,872 (WARNING) - django.request - Not Found: /favicon.ico
2024-01-29 11:58:25,255 (ERROR) - django.request - Internal Server Error: /api/iot/ws/AC118/
Traceback (most recent call last):
  File "/home/sabbir/zenith-sys/zenith/.venv/lib/python3.10/site-packages/django/db/backends/base/base.py", line 289, in ensure_connection
    self.connect()
  File "/home/sabbir/zenith-sys/zenith/.venv/lib/python3.10/site-packages/django/utils/asyncio.py", line 26, in inner
    return func(*args, **kwargs)
  File "/home/sabbir/zenith-sys/zenith/.venv/lib/python3.10/site-packages/django/db/backends/base/base.py", line 270, in connect
    self.connection = self.get_new_connection(conn_params)
  File "/home/sabbir/zenith-sys/zenith/.venv/lib/python3.10/site-packages/django/utils/asyncio.py", line 26, in inner
    return func(*args, **kwargs)
  File "/home/sabbir/zenith-sys/zenith/.venv/lib/python3.10/site-packages/django/db/backends/postgresql/base.py", line 275, in get_new_connection
    connection = self.Database.connect(**conn_params)
  File "/home/sabbir/zenith-sys/zenith/.venv/lib/python3.10/site-packages/psycopg2/__init__.py", line 122, in connect
    conn = _connect(dsn, connection_factory=connection_factory, **kwasync)
psycopg2.OperationalError: could not translate host name "postgres" to address: Name or service not known


The above exception was the direct cause of the following exception:

Traceback (most recent call last):
  File "/home/sabbir/zenith-sys/zenith/.venv/lib/python3.10/site-packages/asgiref/sync.py", line 534, in thread_handler
    raise exc_info[1]
  File "/home/sabbir/zenith-sys/zenith/.venv/lib/python3.10/site-packages/django/core/handlers/exception.py", line 42, in inner
    response = await get_response(request)
  File "/home/sabbir/zenith-sys/zenith/.venv/lib/python3.10/site-packages/django/core/handlers/base.py", line 253, in _get_response_async
    response = await wrapped_callback(
  File "/home/sabbir/zenith-sys/zenith/.venv/lib/python3.10/site-packages/asgiref/sync.py", line 479, in __call__
    ret: _R = await loop.run_in_executor(
  File "/home/sabbir/zenith-sys/zenith/.venv/lib/python3.10/site-packages/asgiref/current_thread_executor.py", line 40, in run
    result = self.fn(*self.args, **self.kwargs)
  File "/home/sabbir/zenith-sys/zenith/.venv/lib/python3.10/site-packages/asgiref/sync.py", line 538, in thread_handler
    return func(*args, **kwargs)
  File "/home/sabbir/zenith-sys/zenith/.venv/lib/python3.10/site-packages/django/views/generic/base.py", line 104, in view
    return self.dispatch(request, *args, **kwargs)
  File "/home/sabbir/zenith-sys/zenith/.venv/lib/python3.10/site-packages/django/views/generic/base.py", line 143, in dispatch
    return handler(request, *args, **kwargs)
  File "/home/sabbir/zenith-sys/zenith/.venv/lib/python3.10/site-packages/django/views/generic/base.py", line 226, in get
    context = self.get_context_data(**kwargs)
  File "/home/sabbir/zenith-sys/zenith/iot/views.py", line 45, in get_context_data
    topic = Device.objects.get(client_id=device_id).topic
  File "/home/sabbir/zenith-sys/zenith/.venv/lib/python3.10/site-packages/django/db/models/manager.py", line 87, in manager_method
    return getattr(self.get_queryset(), name)(*args, **kwargs)
  File "/home/sabbir/zenith-sys/zenith/.venv/lib/python3.10/site-packages/django/db/models/query.py", line 633, in get
    num = len(clone)
  File "/home/sabbir/zenith-sys/zenith/.venv/lib/python3.10/site-packages/django/db/models/query.py", line 380, in __len__
    self._fetch_all()
  File "/home/sabbir/zenith-sys/zenith/.venv/lib/python3.10/site-packages/django/db/models/query.py", line 1881, in _fetch_all
    self._result_cache = list(self._iterable_class(self))
  File "/home/sabbir/zenith-sys/zenith/.venv/lib/python3.10/site-packages/django/db/models/query.py", line 91, in __iter__
    results = compiler.execute_sql(
  File "/home/sabbir/zenith-sys/zenith/.venv/lib/python3.10/site-packages/django/db/models/sql/compiler.py", line 1560, in execute_sql
    cursor = self.connection.cursor()
  File "/home/sabbir/zenith-sys/zenith/.venv/lib/python3.10/site-packages/django/utils/asyncio.py", line 26, in inner
    return func(*args, **kwargs)
  File "/home/sabbir/zenith-sys/zenith/.venv/lib/python3.10/site-packages/django/db/backends/base/base.py", line 330, in cursor
    return self._cursor()
  File "/home/sabbir/zenith-sys/zenith/.venv/lib/python3.10/site-packages/django/db/backends/base/base.py", line 306, in _cursor
    self.ensure_connection()
  File "/home/sabbir/zenith-sys/zenith/.venv/lib/python3.10/site-packages/django/utils/asyncio.py", line 26, in inner
    return func(*args, **kwargs)
  File "/home/sabbir/zenith-sys/zenith/.venv/lib/python3.10/site-packages/django/db/backends/base/base.py", line 288, in ensure_connection
    with self.wrap_database_errors:
  File "/home/sabbir/zenith-sys/zenith/.venv/lib/python3.10/site-packages/django/db/utils.py", line 91, in __exit__
    raise dj_exc_value.with_traceback(traceback) from exc_value
  File "/home/sabbir/zenith-sys/zenith/.venv/lib/python3.10/site-packages/django/db/backends/base/base.py", line 289, in ensure_connection
    self.connect()
  File "/home/sabbir/zenith-sys/zenith/.venv/lib/python3.10/site-packages/django/utils/asyncio.py", line 26, in inner
    return func(*args, **kwargs)
  File "/home/sabbir/zenith-sys/zenith/.venv/lib/python3.10/site-packages/django/db/backends/base/base.py", line 270, in connect
    self.connection = self.get_new_connection(conn_params)
  File "/home/sabbir/zenith-sys/zenith/.venv/lib/python3.10/site-packages/django/utils/asyncio.py", line 26, in inner
    return func(*args, **kwargs)
  File "/home/sabbir/zenith-sys/zenith/.venv/lib/python3.10/site-packages/django/db/backends/postgresql/base.py", line 275, in get_new_connection
    connection = self.Database.connect(**conn_params)
  File "/home/sabbir/zenith-sys/zenith/.venv/lib/python3.10/site-packages/psycopg2/__init__.py", line 122, in connect
    conn = _connect(dsn, connection_factory=connection_factory, **kwasync)
django.db.utils.OperationalError: could not translate host name "postgres" to address: Name or service not known

2024-01-29 11:58:46,047 (ERROR) - django.request - Internal Server Error: /api/iot/ws/AC118/
Traceback (most recent call last):
  File "/home/sabbir/zenith-sys/zenith/.venv/lib/python3.10/site-packages/django/db/backends/base/base.py", line 289, in ensure_connection
    self.connect()
  File "/home/sabbir/zenith-sys/zenith/.venv/lib/python3.10/site-packages/django/utils/asyncio.py", line 26, in inner
    return func(*args, **kwargs)
  File "/home/sabbir/zenith-sys/zenith/.venv/lib/python3.10/site-packages/django/db/backends/base/base.py", line 270, in connect
    self.connection = self.get_new_connection(conn_params)
  File "/home/sabbir/zenith-sys/zenith/.venv/lib/python3.10/site-packages/django/utils/asyncio.py", line 26, in inner
    return func(*args, **kwargs)
  File "/home/sabbir/zenith-sys/zenith/.venv/lib/python3.10/site-packages/django/db/backends/postgresql/base.py", line 275, in get_new_connection
    connection = self.Database.connect(**conn_params)
  File "/home/sabbir/zenith-sys/zenith/.venv/lib/python3.10/site-packages/psycopg2/__init__.py", line 122, in connect
    conn = _connect(dsn, connection_factory=connection_factory, **kwasync)
psycopg2.OperationalError: could not translate host name "postgres" to address: Name or service not known


The above exception was the direct cause of the following exception:

Traceback (most recent call last):
  File "/home/sabbir/zenith-sys/zenith/.venv/lib/python3.10/site-packages/asgiref/sync.py", line 534, in thread_handler
    raise exc_info[1]
  File "/home/sabbir/zenith-sys/zenith/.venv/lib/python3.10/site-packages/django/core/handlers/exception.py", line 42, in inner
    response = await get_response(request)
  File "/home/sabbir/zenith-sys/zenith/.venv/lib/python3.10/site-packages/django/core/handlers/base.py", line 253, in _get_response_async
    response = await wrapped_callback(
  File "/home/sabbir/zenith-sys/zenith/.venv/lib/python3.10/site-packages/asgiref/sync.py", line 479, in __call__
    ret: _R = await loop.run_in_executor(
  File "/home/sabbir/zenith-sys/zenith/.venv/lib/python3.10/site-packages/asgiref/current_thread_executor.py", line 40, in run
    result = self.fn(*self.args, **self.kwargs)
  File "/home/sabbir/zenith-sys/zenith/.venv/lib/python3.10/site-packages/asgiref/sync.py", line 538, in thread_handler
    return func(*args, **kwargs)
  File "/home/sabbir/zenith-sys/zenith/.venv/lib/python3.10/site-packages/django/views/generic/base.py", line 104, in view
    return self.dispatch(request, *args, **kwargs)
  File "/home/sabbir/zenith-sys/zenith/.venv/lib/python3.10/site-packages/django/views/generic/base.py", line 143, in dispatch
    return handler(request, *args, **kwargs)
  File "/home/sabbir/zenith-sys/zenith/.venv/lib/python3.10/site-packages/django/views/generic/base.py", line 226, in get
    context = self.get_context_data(**kwargs)
  File "/home/sabbir/zenith-sys/zenith/iot/views.py", line 45, in get_context_data
    topic = Device.objects.get(client_id=device_id).topic
  File "/home/sabbir/zenith-sys/zenith/.venv/lib/python3.10/site-packages/django/db/models/manager.py", line 87, in manager_method
    return getattr(self.get_queryset(), name)(*args, **kwargs)
  File "/home/sabbir/zenith-sys/zenith/.venv/lib/python3.10/site-packages/django/db/models/query.py", line 633, in get
    num = len(clone)
  File "/home/sabbir/zenith-sys/zenith/.venv/lib/python3.10/site-packages/django/db/models/query.py", line 380, in __len__
    self._fetch_all()
  File "/home/sabbir/zenith-sys/zenith/.venv/lib/python3.10/site-packages/django/db/models/query.py", line 1881, in _fetch_all
    self._result_cache = list(self._iterable_class(self))
  File "/home/sabbir/zenith-sys/zenith/.venv/lib/python3.10/site-packages/django/db/models/query.py", line 91, in __iter__
    results = compiler.execute_sql(
  File "/home/sabbir/zenith-sys/zenith/.venv/lib/python3.10/site-packages/django/db/models/sql/compiler.py", line 1560, in execute_sql
    cursor = self.connection.cursor()
  File "/home/sabbir/zenith-sys/zenith/.venv/lib/python3.10/site-packages/django/utils/asyncio.py", line 26, in inner
    return func(*args, **kwargs)
  File "/home/sabbir/zenith-sys/zenith/.venv/lib/python3.10/site-packages/django/db/backends/base/base.py", line 330, in cursor
    return self._cursor()
  File "/home/sabbir/zenith-sys/zenith/.venv/lib/python3.10/site-packages/django/db/backends/base/base.py", line 306, in _cursor
    self.ensure_connection()
  File "/home/sabbir/zenith-sys/zenith/.venv/lib/python3.10/site-packages/django/utils/asyncio.py", line 26, in inner
    return func(*args, **kwargs)
  File "/home/sabbir/zenith-sys/zenith/.venv/lib/python3.10/site-packages/django/db/backends/base/base.py", line 288, in ensure_connection
    with self.wrap_database_errors:
  File "/home/sabbir/zenith-sys/zenith/.venv/lib/python3.10/site-packages/django/db/utils.py", line 91, in __exit__
    raise dj_exc_value.with_traceback(traceback) from exc_value
  File "/home/sabbir/zenith-sys/zenith/.venv/lib/python3.10/site-packages/django/db/backends/base/base.py", line 289, in ensure_connection
    self.connect()
  File "/home/sabbir/zenith-sys/zenith/.venv/lib/python3.10/site-packages/django/utils/asyncio.py", line 26, in inner
    return func(*args, **kwargs)
  File "/home/sabbir/zenith-sys/zenith/.venv/lib/python3.10/site-packages/django/db/backends/base/base.py", line 270, in connect
    self.connection = self.get_new_connection(conn_params)
  File "/home/sabbir/zenith-sys/zenith/.venv/lib/python3.10/site-packages/django/utils/asyncio.py", line 26, in inner
    return func(*args, **kwargs)
  File "/home/sabbir/zenith-sys/zenith/.venv/lib/python3.10/site-packages/django/db/backends/postgresql/base.py", line 275, in get_new_connection
    connection = self.Database.connect(**conn_params)
  File "/home/sabbir/zenith-sys/zenith/.venv/lib/python3.10/site-packages/psycopg2/__init__.py", line 122, in connect
    conn = _connect(dsn, connection_factory=connection_factory, **kwasync)
django.db.utils.OperationalError: could not translate host name "postgres" to address: Name or service not known

2024-01-29 11:58:46,578 (WARNING) - django.request - Not Found: /favicon.ico
2024-01-29 11:59:24,001 (ERROR) - django.request - Internal Server Error: /api/iot/ws/AC118/
Traceback (most recent call last):
  File "/home/sabbir/zenith-sys/zenith/.venv/lib/python3.10/site-packages/django/db/backends/base/base.py", line 289, in ensure_connection
    self.connect()
  File "/home/sabbir/zenith-sys/zenith/.venv/lib/python3.10/site-packages/django/utils/asyncio.py", line 26, in inner
    return func(*args, **kwargs)
  File "/home/sabbir/zenith-sys/zenith/.venv/lib/python3.10/site-packages/django/db/backends/base/base.py", line 270, in connect
    self.connection = self.get_new_connection(conn_params)
  File "/home/sabbir/zenith-sys/zenith/.venv/lib/python3.10/site-packages/django/utils/asyncio.py", line 26, in inner
    return func(*args, **kwargs)
  File "/home/sabbir/zenith-sys/zenith/.venv/lib/python3.10/site-packages/django/db/backends/postgresql/base.py", line 275, in get_new_connection
    connection = self.Database.connect(**conn_params)
  File "/home/sabbir/zenith-sys/zenith/.venv/lib/python3.10/site-packages/psycopg2/__init__.py", line 122, in connect
    conn = _connect(dsn, connection_factory=connection_factory, **kwasync)
psycopg2.OperationalError: could not translate host name "postgres" to address: Name or service not known


The above exception was the direct cause of the following exception:

Traceback (most recent call last):
  File "/home/sabbir/zenith-sys/zenith/.venv/lib/python3.10/site-packages/asgiref/sync.py", line 534, in thread_handler
    raise exc_info[1]
  File "/home/sabbir/zenith-sys/zenith/.venv/lib/python3.10/site-packages/django/core/handlers/exception.py", line 42, in inner
    response = await get_response(request)
  File "/home/sabbir/zenith-sys/zenith/.venv/lib/python3.10/site-packages/django/core/handlers/base.py", line 253, in _get_response_async
    response = await wrapped_callback(
  File "/home/sabbir/zenith-sys/zenith/.venv/lib/python3.10/site-packages/asgiref/sync.py", line 479, in __call__
    ret: _R = await loop.run_in_executor(
  File "/home/sabbir/zenith-sys/zenith/.venv/lib/python3.10/site-packages/asgiref/current_thread_executor.py", line 40, in run
    result = self.fn(*self.args, **self.kwargs)
  File "/home/sabbir/zenith-sys/zenith/.venv/lib/python3.10/site-packages/asgiref/sync.py", line 538, in thread_handler
    return func(*args, **kwargs)
  File "/home/sabbir/zenith-sys/zenith/.venv/lib/python3.10/site-packages/django/views/generic/base.py", line 104, in view
    return self.dispatch(request, *args, **kwargs)
  File "/home/sabbir/zenith-sys/zenith/.venv/lib/python3.10/site-packages/django/views/generic/base.py", line 143, in dispatch
    return handler(request, *args, **kwargs)
  File "/home/sabbir/zenith-sys/zenith/.venv/lib/python3.10/site-packages/django/views/generic/base.py", line 226, in get
    context = self.get_context_data(**kwargs)
  File "/home/sabbir/zenith-sys/zenith/iot/views.py", line 45, in get_context_data
    topic = Device.objects.get(client_id=device_id).topic
  File "/home/sabbir/zenith-sys/zenith/.venv/lib/python3.10/site-packages/django/db/models/manager.py", line 87, in manager_method
    return getattr(self.get_queryset(), name)(*args, **kwargs)
  File "/home/sabbir/zenith-sys/zenith/.venv/lib/python3.10/site-packages/django/db/models/query.py", line 633, in get
    num = len(clone)
  File "/home/sabbir/zenith-sys/zenith/.venv/lib/python3.10/site-packages/django/db/models/query.py", line 380, in __len__
    self._fetch_all()
  File "/home/sabbir/zenith-sys/zenith/.venv/lib/python3.10/site-packages/django/db/models/query.py", line 1881, in _fetch_all
    self._result_cache = list(self._iterable_class(self))
  File "/home/sabbir/zenith-sys/zenith/.venv/lib/python3.10/site-packages/django/db/models/query.py", line 91, in __iter__
    results = compiler.execute_sql(
  File "/home/sabbir/zenith-sys/zenith/.venv/lib/python3.10/site-packages/django/db/models/sql/compiler.py", line 1560, in execute_sql
    cursor = self.connection.cursor()
  File "/home/sabbir/zenith-sys/zenith/.venv/lib/python3.10/site-packages/django/utils/asyncio.py", line 26, in inner
    return func(*args, **kwargs)
  File "/home/sabbir/zenith-sys/zenith/.venv/lib/python3.10/site-packages/django/db/backends/base/base.py", line 330, in cursor
    return self._cursor()
  File "/home/sabbir/zenith-sys/zenith/.venv/lib/python3.10/site-packages/django/db/backends/base/base.py", line 306, in _cursor
    self.ensure_connection()
  File "/home/sabbir/zenith-sys/zenith/.venv/lib/python3.10/site-packages/django/utils/asyncio.py", line 26, in inner
    return func(*args, **kwargs)
  File "/home/sabbir/zenith-sys/zenith/.venv/lib/python3.10/site-packages/django/db/backends/base/base.py", line 288, in ensure_connection
    with self.wrap_database_errors:
  File "/home/sabbir/zenith-sys/zenith/.venv/lib/python3.10/site-packages/django/db/utils.py", line 91, in __exit__
    raise dj_exc_value.with_traceback(traceback) from exc_value
  File "/home/sabbir/zenith-sys/zenith/.venv/lib/python3.10/site-packages/django/db/backends/base/base.py", line 289, in ensure_connection
    self.connect()
  File "/home/sabbir/zenith-sys/zenith/.venv/lib/python3.10/site-packages/django/utils/asyncio.py", line 26, in inner
    return func(*args, **kwargs)
  File "/home/sabbir/zenith-sys/zenith/.venv/lib/python3.10/site-packages/django/db/backends/base/base.py", line 270, in connect
    self.connection = self.get_new_connection(conn_params)
  File "/home/sabbir/zenith-sys/zenith/.venv/lib/python3.10/site-packages/django/utils/asyncio.py", line 26, in inner
    return func(*args, **kwargs)
  File "/home/sabbir/zenith-sys/zenith/.venv/lib/python3.10/site-packages/django/db/backends/postgresql/base.py", line 275, in get_new_connection
    connection = self.Database.connect(**conn_params)
  File "/home/sabbir/zenith-sys/zenith/.venv/lib/python3.10/site-packages/psycopg2/__init__.py", line 122, in connect
    conn = _connect(dsn, connection_factory=connection_factory, **kwasync)
django.db.utils.OperationalError: could not translate host name "postgres" to address: Name or service not known

2024-01-29 12:00:10,646 (ERROR) - django.request - Internal Server Error: /api/iot/ws/AC118/
Traceback (most recent call last):
  File "/home/sabbir/zenith-sys/zenith/.venv/lib/python3.10/site-packages/django/db/backends/base/base.py", line 289, in ensure_connection
    self.connect()
  File "/home/sabbir/zenith-sys/zenith/.venv/lib/python3.10/site-packages/django/utils/asyncio.py", line 26, in inner
    return func(*args, **kwargs)
  File "/home/sabbir/zenith-sys/zenith/.venv/lib/python3.10/site-packages/django/db/backends/base/base.py", line 270, in connect
    self.connection = self.get_new_connection(conn_params)
  File "/home/sabbir/zenith-sys/zenith/.venv/lib/python3.10/site-packages/django/utils/asyncio.py", line 26, in inner
    return func(*args, **kwargs)
  File "/home/sabbir/zenith-sys/zenith/.venv/lib/python3.10/site-packages/django/db/backends/postgresql/base.py", line 275, in get_new_connection
    connection = self.Database.connect(**conn_params)
  File "/home/sabbir/zenith-sys/zenith/.venv/lib/python3.10/site-packages/psycopg2/__init__.py", line 122, in connect
    conn = _connect(dsn, connection_factory=connection_factory, **kwasync)
psycopg2.OperationalError: could not translate host name "postgres" to address: Name or service not known


The above exception was the direct cause of the following exception:

Traceback (most recent call last):
  File "/home/sabbir/zenith-sys/zenith/.venv/lib/python3.10/site-packages/asgiref/sync.py", line 534, in thread_handler
    raise exc_info[1]
  File "/home/sabbir/zenith-sys/zenith/.venv/lib/python3.10/site-packages/django/core/handlers/exception.py", line 42, in inner
    response = await get_response(request)
  File "/home/sabbir/zenith-sys/zenith/.venv/lib/python3.10/site-packages/django/core/handlers/base.py", line 253, in _get_response_async
    response = await wrapped_callback(
  File "/home/sabbir/zenith-sys/zenith/.venv/lib/python3.10/site-packages/asgiref/sync.py", line 479, in __call__
    ret: _R = await loop.run_in_executor(
  File "/home/sabbir/zenith-sys/zenith/.venv/lib/python3.10/site-packages/asgiref/current_thread_executor.py", line 40, in run
    result = self.fn(*self.args, **self.kwargs)
  File "/home/sabbir/zenith-sys/zenith/.venv/lib/python3.10/site-packages/asgiref/sync.py", line 538, in thread_handler
    return func(*args, **kwargs)
  File "/home/sabbir/zenith-sys/zenith/.venv/lib/python3.10/site-packages/django/views/generic/base.py", line 104, in view
    return self.dispatch(request, *args, **kwargs)
  File "/home/sabbir/zenith-sys/zenith/.venv/lib/python3.10/site-packages/django/views/generic/base.py", line 143, in dispatch
    return handler(request, *args, **kwargs)
  File "/home/sabbir/zenith-sys/zenith/.venv/lib/python3.10/site-packages/django/views/generic/base.py", line 226, in get
    context = self.get_context_data(**kwargs)
  File "/home/sabbir/zenith-sys/zenith/iot/views.py", line 45, in get_context_data
    topic = Device.objects.get(client_id=device_id).topic
  File "/home/sabbir/zenith-sys/zenith/.venv/lib/python3.10/site-packages/django/db/models/manager.py", line 87, in manager_method
    return getattr(self.get_queryset(), name)(*args, **kwargs)
  File "/home/sabbir/zenith-sys/zenith/.venv/lib/python3.10/site-packages/django/db/models/query.py", line 633, in get
    num = len(clone)
  File "/home/sabbir/zenith-sys/zenith/.venv/lib/python3.10/site-packages/django/db/models/query.py", line 380, in __len__
    self._fetch_all()
  File "/home/sabbir/zenith-sys/zenith/.venv/lib/python3.10/site-packages/django/db/models/query.py", line 1881, in _fetch_all
    self._result_cache = list(self._iterable_class(self))
  File "/home/sabbir/zenith-sys/zenith/.venv/lib/python3.10/site-packages/django/db/models/query.py", line 91, in __iter__
    results = compiler.execute_sql(
  File "/home/sabbir/zenith-sys/zenith/.venv/lib/python3.10/site-packages/django/db/models/sql/compiler.py", line 1560, in execute_sql
    cursor = self.connection.cursor()
  File "/home/sabbir/zenith-sys/zenith/.venv/lib/python3.10/site-packages/django/utils/asyncio.py", line 26, in inner
    return func(*args, **kwargs)
  File "/home/sabbir/zenith-sys/zenith/.venv/lib/python3.10/site-packages/django/db/backends/base/base.py", line 330, in cursor
    return self._cursor()
  File "/home/sabbir/zenith-sys/zenith/.venv/lib/python3.10/site-packages/django/db/backends/base/base.py", line 306, in _cursor
    self.ensure_connection()
  File "/home/sabbir/zenith-sys/zenith/.venv/lib/python3.10/site-packages/django/utils/asyncio.py", line 26, in inner
    return func(*args, **kwargs)
  File "/home/sabbir/zenith-sys/zenith/.venv/lib/python3.10/site-packages/django/db/backends/base/base.py", line 288, in ensure_connection
    with self.wrap_database_errors:
  File "/home/sabbir/zenith-sys/zenith/.venv/lib/python3.10/site-packages/django/db/utils.py", line 91, in __exit__
    raise dj_exc_value.with_traceback(traceback) from exc_value
  File "/home/sabbir/zenith-sys/zenith/.venv/lib/python3.10/site-packages/django/db/backends/base/base.py", line 289, in ensure_connection
    self.connect()
  File "/home/sabbir/zenith-sys/zenith/.venv/lib/python3.10/site-packages/django/utils/asyncio.py", line 26, in inner
    return func(*args, **kwargs)
  File "/home/sabbir/zenith-sys/zenith/.venv/lib/python3.10/site-packages/django/db/backends/base/base.py", line 270, in connect
    self.connection = self.get_new_connection(conn_params)
  File "/home/sabbir/zenith-sys/zenith/.venv/lib/python3.10/site-packages/django/utils/asyncio.py", line 26, in inner
    return func(*args, **kwargs)
  File "/home/sabbir/zenith-sys/zenith/.venv/lib/python3.10/site-packages/django/db/backends/postgresql/base.py", line 275, in get_new_connection
    connection = self.Database.connect(**conn_params)
  File "/home/sabbir/zenith-sys/zenith/.venv/lib/python3.10/site-packages/psycopg2/__init__.py", line 122, in connect
    conn = _connect(dsn, connection_factory=connection_factory, **kwasync)
django.db.utils.OperationalError: could not translate host name "postgres" to address: Name or service not known

2024-01-29 12:02:29,448 (INFO) - django.utils.autoreload - Watching for file changes with StatReloader
2024-01-29 12:02:36,609 (WARNING) - django.request - Not Found: /ws/device/AC118/
2024-01-29 17:14:00,663 (ERROR) - django.request - Internal Server Error: /api/iot/ws/AC118/
Traceback (most recent call last):
  File "/usr/local/lib/python3.10/site-packages/asgiref/sync.py", line 534, in thread_handler
    raise exc_info[1]
  File "/usr/local/lib/python3.10/site-packages/django/core/handlers/exception.py", line 42, in inner
    response = await get_response(request)
  File "/usr/local/lib/python3.10/site-packages/django/core/handlers/base.py", line 253, in _get_response_async
    response = await wrapped_callback(
  File "/usr/local/lib/python3.10/site-packages/asgiref/sync.py", line 479, in __call__
    ret: _R = await loop.run_in_executor(
  File "/usr/local/lib/python3.10/site-packages/asgiref/current_thread_executor.py", line 40, in run
    result = self.fn(*self.args, **self.kwargs)
  File "/usr/local/lib/python3.10/site-packages/asgiref/sync.py", line 538, in thread_handler
    return func(*args, **kwargs)
  File "/usr/local/lib/python3.10/site-packages/django/views/generic/base.py", line 104, in view
    return self.dispatch(request, *args, **kwargs)
  File "/usr/local/lib/python3.10/site-packages/django/views/generic/base.py", line 143, in dispatch
    return handler(request, *args, **kwargs)
  File "/usr/local/lib/python3.10/site-packages/django/views/generic/base.py", line 226, in get
    context = self.get_context_data(**kwargs)
  File "/app/iot/views.py", line 43, in get_context_data
    topic = Device.objects.get(client_id=device_id).topic
  File "/usr/local/lib/python3.10/site-packages/django/db/models/manager.py", line 87, in manager_method
    return getattr(self.get_queryset(), name)(*args, **kwargs)
  File "/usr/local/lib/python3.10/site-packages/django/db/models/query.py", line 637, in get
    raise self.model.DoesNotExist(
iot.models.Device.DoesNotExist: Device matching query does not exist.
2024-01-29 17:24:38,010 (WARNING) - django.request - Not Found: /api/
2024-02-03 07:28:28,778 (ERROR) - django.request - Internal Server Error: /api/iot/ws/AC118/
Traceback (most recent call last):
  File "/home/sabbir/zenith-sys/zenith/.venv/lib/python3.10/site-packages/django/db/backends/base/base.py", line 289, in ensure_connection
    self.connect()
  File "/home/sabbir/zenith-sys/zenith/.venv/lib/python3.10/site-packages/django/utils/asyncio.py", line 26, in inner
    return func(*args, **kwargs)
  File "/home/sabbir/zenith-sys/zenith/.venv/lib/python3.10/site-packages/django/db/backends/base/base.py", line 270, in connect
    self.connection = self.get_new_connection(conn_params)
  File "/home/sabbir/zenith-sys/zenith/.venv/lib/python3.10/site-packages/django/utils/asyncio.py", line 26, in inner
    return func(*args, **kwargs)
  File "/home/sabbir/zenith-sys/zenith/.venv/lib/python3.10/site-packages/django/db/backends/postgresql/base.py", line 275, in get_new_connection
    connection = self.Database.connect(**conn_params)
  File "/home/sabbir/zenith-sys/zenith/.venv/lib/python3.10/site-packages/psycopg2/__init__.py", line 122, in connect
    conn = _connect(dsn, connection_factory=connection_factory, **kwasync)
psycopg2.OperationalError: could not translate host name "postgres" to address: Name or service not known


The above exception was the direct cause of the following exception:

Traceback (most recent call last):
  File "/home/sabbir/zenith-sys/zenith/.venv/lib/python3.10/site-packages/asgiref/sync.py", line 534, in thread_handler
    raise exc_info[1]
  File "/home/sabbir/zenith-sys/zenith/.venv/lib/python3.10/site-packages/django/core/handlers/exception.py", line 42, in inner
    response = await get_response(request)
  File "/home/sabbir/zenith-sys/zenith/.venv/lib/python3.10/site-packages/django/core/handlers/base.py", line 253, in _get_response_async
    response = await wrapped_callback(
  File "/home/sabbir/zenith-sys/zenith/.venv/lib/python3.10/site-packages/asgiref/sync.py", line 479, in __call__
    ret: _R = await loop.run_in_executor(
  File "/home/sabbir/zenith-sys/zenith/.venv/lib/python3.10/site-packages/asgiref/current_thread_executor.py", line 40, in run
    result = self.fn(*self.args, **self.kwargs)
  File "/home/sabbir/zenith-sys/zenith/.venv/lib/python3.10/site-packages/asgiref/sync.py", line 538, in thread_handler
    return func(*args, **kwargs)
  File "/home/sabbir/zenith-sys/zenith/.venv/lib/python3.10/site-packages/django/views/generic/base.py", line 104, in view
    return self.dispatch(request, *args, **kwargs)
  File "/home/sabbir/zenith-sys/zenith/.venv/lib/python3.10/site-packages/django/views/generic/base.py", line 143, in dispatch
    return handler(request, *args, **kwargs)
  File "/home/sabbir/zenith-sys/zenith/.venv/lib/python3.10/site-packages/django/views/generic/base.py", line 226, in get
    context = self.get_context_data(**kwargs)
  File "/home/sabbir/zenith-sys/zenith/iot/views.py", line 43, in get_context_data
    topic = Device.objects.get(client_id=device_id).topic
  File "/home/sabbir/zenith-sys/zenith/.venv/lib/python3.10/site-packages/django/db/models/manager.py", line 87, in manager_method
    return getattr(self.get_queryset(), name)(*args, **kwargs)
  File "/home/sabbir/zenith-sys/zenith/.venv/lib/python3.10/site-packages/django/db/models/query.py", line 633, in get
    num = len(clone)
  File "/home/sabbir/zenith-sys/zenith/.venv/lib/python3.10/site-packages/django/db/models/query.py", line 380, in __len__
    self._fetch_all()
  File "/home/sabbir/zenith-sys/zenith/.venv/lib/python3.10/site-packages/django/db/models/query.py", line 1881, in _fetch_all
    self._result_cache = list(self._iterable_class(self))
  File "/home/sabbir/zenith-sys/zenith/.venv/lib/python3.10/site-packages/django/db/models/query.py", line 91, in __iter__
    results = compiler.execute_sql(
  File "/home/sabbir/zenith-sys/zenith/.venv/lib/python3.10/site-packages/django/db/models/sql/compiler.py", line 1560, in execute_sql
    cursor = self.connection.cursor()
  File "/home/sabbir/zenith-sys/zenith/.venv/lib/python3.10/site-packages/django/utils/asyncio.py", line 26, in inner
    return func(*args, **kwargs)
  File "/home/sabbir/zenith-sys/zenith/.venv/lib/python3.10/site-packages/django/db/backends/base/base.py", line 330, in cursor
    return self._cursor()
  File "/home/sabbir/zenith-sys/zenith/.venv/lib/python3.10/site-packages/django/db/backends/base/base.py", line 306, in _cursor
    self.ensure_connection()
  File "/home/sabbir/zenith-sys/zenith/.venv/lib/python3.10/site-packages/django/utils/asyncio.py", line 26, in inner
    return func(*args, **kwargs)
  File "/home/sabbir/zenith-sys/zenith/.venv/lib/python3.10/site-packages/django/db/backends/base/base.py", line 288, in ensure_connection
    with self.wrap_database_errors:
  File "/home/sabbir/zenith-sys/zenith/.venv/lib/python3.10/site-packages/django/db/utils.py", line 91, in __exit__
    raise dj_exc_value.with_traceback(traceback) from exc_value
  File "/home/sabbir/zenith-sys/zenith/.venv/lib/python3.10/site-packages/django/db/backends/base/base.py", line 289, in ensure_connection
    self.connect()
  File "/home/sabbir/zenith-sys/zenith/.venv/lib/python3.10/site-packages/django/utils/asyncio.py", line 26, in inner
    return func(*args, **kwargs)
  File "/home/sabbir/zenith-sys/zenith/.venv/lib/python3.10/site-packages/django/db/backends/base/base.py", line 270, in connect
    self.connection = self.get_new_connection(conn_params)
  File "/home/sabbir/zenith-sys/zenith/.venv/lib/python3.10/site-packages/django/utils/asyncio.py", line 26, in inner
    return func(*args, **kwargs)
  File "/home/sabbir/zenith-sys/zenith/.venv/lib/python3.10/site-packages/django/db/backends/postgresql/base.py", line 275, in get_new_connection
    connection = self.Database.connect(**conn_params)
  File "/home/sabbir/zenith-sys/zenith/.venv/lib/python3.10/site-packages/psycopg2/__init__.py", line 122, in connect
    conn = _connect(dsn, connection_factory=connection_factory, **kwasync)
django.db.utils.OperationalError: could not translate host name "postgres" to address: Name or service not known

2024-02-03 07:28:47,062 (ERROR) - django.request - Internal Server Error: /api/iot/ws/AC118/
Traceback (most recent call last):
  File "/home/sabbir/zenith-sys/zenith/.venv/lib/python3.10/site-packages/django/db/backends/base/base.py", line 289, in ensure_connection
    self.connect()
  File "/home/sabbir/zenith-sys/zenith/.venv/lib/python3.10/site-packages/django/utils/asyncio.py", line 26, in inner
    return func(*args, **kwargs)
  File "/home/sabbir/zenith-sys/zenith/.venv/lib/python3.10/site-packages/django/db/backends/base/base.py", line 270, in connect
    self.connection = self.get_new_connection(conn_params)
  File "/home/sabbir/zenith-sys/zenith/.venv/lib/python3.10/site-packages/django/utils/asyncio.py", line 26, in inner
    return func(*args, **kwargs)
  File "/home/sabbir/zenith-sys/zenith/.venv/lib/python3.10/site-packages/django/db/backends/postgresql/base.py", line 275, in get_new_connection
    connection = self.Database.connect(**conn_params)
  File "/home/sabbir/zenith-sys/zenith/.venv/lib/python3.10/site-packages/psycopg2/__init__.py", line 122, in connect
    conn = _connect(dsn, connection_factory=connection_factory, **kwasync)
psycopg2.OperationalError: could not translate host name "postgres" to address: Name or service not known


The above exception was the direct cause of the following exception:

Traceback (most recent call last):
  File "/home/sabbir/zenith-sys/zenith/.venv/lib/python3.10/site-packages/asgiref/sync.py", line 534, in thread_handler
    raise exc_info[1]
  File "/home/sabbir/zenith-sys/zenith/.venv/lib/python3.10/site-packages/django/core/handlers/exception.py", line 42, in inner
    response = await get_response(request)
  File "/home/sabbir/zenith-sys/zenith/.venv/lib/python3.10/site-packages/django/core/handlers/base.py", line 253, in _get_response_async
    response = await wrapped_callback(
  File "/home/sabbir/zenith-sys/zenith/.venv/lib/python3.10/site-packages/asgiref/sync.py", line 479, in __call__
    ret: _R = await loop.run_in_executor(
  File "/home/sabbir/zenith-sys/zenith/.venv/lib/python3.10/site-packages/asgiref/current_thread_executor.py", line 40, in run
    result = self.fn(*self.args, **self.kwargs)
  File "/home/sabbir/zenith-sys/zenith/.venv/lib/python3.10/site-packages/asgiref/sync.py", line 538, in thread_handler
    return func(*args, **kwargs)
  File "/home/sabbir/zenith-sys/zenith/.venv/lib/python3.10/site-packages/django/views/generic/base.py", line 104, in view
    return self.dispatch(request, *args, **kwargs)
  File "/home/sabbir/zenith-sys/zenith/.venv/lib/python3.10/site-packages/django/views/generic/base.py", line 143, in dispatch
    return handler(request, *args, **kwargs)
  File "/home/sabbir/zenith-sys/zenith/.venv/lib/python3.10/site-packages/django/views/generic/base.py", line 226, in get
    context = self.get_context_data(**kwargs)
  File "/home/sabbir/zenith-sys/zenith/iot/views.py", line 43, in get_context_data
    topic = Device.objects.get(client_id=device_id).topic
  File "/home/sabbir/zenith-sys/zenith/.venv/lib/python3.10/site-packages/django/db/models/manager.py", line 87, in manager_method
    return getattr(self.get_queryset(), name)(*args, **kwargs)
  File "/home/sabbir/zenith-sys/zenith/.venv/lib/python3.10/site-packages/django/db/models/query.py", line 633, in get
    num = len(clone)
  File "/home/sabbir/zenith-sys/zenith/.venv/lib/python3.10/site-packages/django/db/models/query.py", line 380, in __len__
    self._fetch_all()
  File "/home/sabbir/zenith-sys/zenith/.venv/lib/python3.10/site-packages/django/db/models/query.py", line 1881, in _fetch_all
    self._result_cache = list(self._iterable_class(self))
  File "/home/sabbir/zenith-sys/zenith/.venv/lib/python3.10/site-packages/django/db/models/query.py", line 91, in __iter__
    results = compiler.execute_sql(
  File "/home/sabbir/zenith-sys/zenith/.venv/lib/python3.10/site-packages/django/db/models/sql/compiler.py", line 1560, in execute_sql
    cursor = self.connection.cursor()
  File "/home/sabbir/zenith-sys/zenith/.venv/lib/python3.10/site-packages/django/utils/asyncio.py", line 26, in inner
    return func(*args, **kwargs)
  File "/home/sabbir/zenith-sys/zenith/.venv/lib/python3.10/site-packages/django/db/backends/base/base.py", line 330, in cursor
    return self._cursor()
  File "/home/sabbir/zenith-sys/zenith/.venv/lib/python3.10/site-packages/django/db/backends/base/base.py", line 306, in _cursor
    self.ensure_connection()
  File "/home/sabbir/zenith-sys/zenith/.venv/lib/python3.10/site-packages/django/utils/asyncio.py", line 26, in inner
    return func(*args, **kwargs)
  File "/home/sabbir/zenith-sys/zenith/.venv/lib/python3.10/site-packages/django/db/backends/base/base.py", line 288, in ensure_connection
    with self.wrap_database_errors:
  File "/home/sabbir/zenith-sys/zenith/.venv/lib/python3.10/site-packages/django/db/utils.py", line 91, in __exit__
    raise dj_exc_value.with_traceback(traceback) from exc_value
  File "/home/sabbir/zenith-sys/zenith/.venv/lib/python3.10/site-packages/django/db/backends/base/base.py", line 289, in ensure_connection
    self.connect()
  File "/home/sabbir/zenith-sys/zenith/.venv/lib/python3.10/site-packages/django/utils/asyncio.py", line 26, in inner
    return func(*args, **kwargs)
  File "/home/sabbir/zenith-sys/zenith/.venv/lib/python3.10/site-packages/django/db/backends/base/base.py", line 270, in connect
    self.connection = self.get_new_connection(conn_params)
  File "/home/sabbir/zenith-sys/zenith/.venv/lib/python3.10/site-packages/django/utils/asyncio.py", line 26, in inner
    return func(*args, **kwargs)
  File "/home/sabbir/zenith-sys/zenith/.venv/lib/python3.10/site-packages/django/db/backends/postgresql/base.py", line 275, in get_new_connection
    connection = self.Database.connect(**conn_params)
  File "/home/sabbir/zenith-sys/zenith/.venv/lib/python3.10/site-packages/psycopg2/__init__.py", line 122, in connect
    conn = _connect(dsn, connection_factory=connection_factory, **kwasync)
django.db.utils.OperationalError: could not translate host name "postgres" to address: Name or service not known

2024-02-03 07:28:50,312 (WARNING) - django.request - Not Found: /favicon.ico
2024-02-03 07:29:24,028 (ERROR) - django.request - Internal Server Error: /api/iot/ws/AC118/
Traceback (most recent call last):
  File "/home/sabbir/zenith-sys/zenith/.venv/lib/python3.10/site-packages/django/db/backends/base/base.py", line 289, in ensure_connection
    self.connect()
  File "/home/sabbir/zenith-sys/zenith/.venv/lib/python3.10/site-packages/django/utils/asyncio.py", line 26, in inner
    return func(*args, **kwargs)
  File "/home/sabbir/zenith-sys/zenith/.venv/lib/python3.10/site-packages/django/db/backends/base/base.py", line 270, in connect
    self.connection = self.get_new_connection(conn_params)
  File "/home/sabbir/zenith-sys/zenith/.venv/lib/python3.10/site-packages/django/utils/asyncio.py", line 26, in inner
    return func(*args, **kwargs)
  File "/home/sabbir/zenith-sys/zenith/.venv/lib/python3.10/site-packages/django/db/backends/postgresql/base.py", line 275, in get_new_connection
    connection = self.Database.connect(**conn_params)
  File "/home/sabbir/zenith-sys/zenith/.venv/lib/python3.10/site-packages/psycopg2/__init__.py", line 122, in connect
    conn = _connect(dsn, connection_factory=connection_factory, **kwasync)
psycopg2.OperationalError: could not translate host name "postgres" to address: Name or service not known


The above exception was the direct cause of the following exception:

Traceback (most recent call last):
  File "/home/sabbir/zenith-sys/zenith/.venv/lib/python3.10/site-packages/asgiref/sync.py", line 534, in thread_handler
    raise exc_info[1]
  File "/home/sabbir/zenith-sys/zenith/.venv/lib/python3.10/site-packages/django/core/handlers/exception.py", line 42, in inner
    response = await get_response(request)
  File "/home/sabbir/zenith-sys/zenith/.venv/lib/python3.10/site-packages/django/core/handlers/base.py", line 253, in _get_response_async
    response = await wrapped_callback(
  File "/home/sabbir/zenith-sys/zenith/.venv/lib/python3.10/site-packages/asgiref/sync.py", line 479, in __call__
    ret: _R = await loop.run_in_executor(
  File "/home/sabbir/zenith-sys/zenith/.venv/lib/python3.10/site-packages/asgiref/current_thread_executor.py", line 40, in run
    result = self.fn(*self.args, **self.kwargs)
  File "/home/sabbir/zenith-sys/zenith/.venv/lib/python3.10/site-packages/asgiref/sync.py", line 538, in thread_handler
    return func(*args, **kwargs)
  File "/home/sabbir/zenith-sys/zenith/.venv/lib/python3.10/site-packages/django/views/generic/base.py", line 104, in view
    return self.dispatch(request, *args, **kwargs)
  File "/home/sabbir/zenith-sys/zenith/.venv/lib/python3.10/site-packages/django/views/generic/base.py", line 143, in dispatch
    return handler(request, *args, **kwargs)
  File "/home/sabbir/zenith-sys/zenith/.venv/lib/python3.10/site-packages/django/views/generic/base.py", line 226, in get
    context = self.get_context_data(**kwargs)
  File "/home/sabbir/zenith-sys/zenith/iot/views.py", line 43, in get_context_data
    topic = Device.objects.get(client_id=device_id).topic
  File "/home/sabbir/zenith-sys/zenith/.venv/lib/python3.10/site-packages/django/db/models/manager.py", line 87, in manager_method
    return getattr(self.get_queryset(), name)(*args, **kwargs)
  File "/home/sabbir/zenith-sys/zenith/.venv/lib/python3.10/site-packages/django/db/models/query.py", line 633, in get
    num = len(clone)
  File "/home/sabbir/zenith-sys/zenith/.venv/lib/python3.10/site-packages/django/db/models/query.py", line 380, in __len__
    self._fetch_all()
  File "/home/sabbir/zenith-sys/zenith/.venv/lib/python3.10/site-packages/django/db/models/query.py", line 1881, in _fetch_all
    self._result_cache = list(self._iterable_class(self))
  File "/home/sabbir/zenith-sys/zenith/.venv/lib/python3.10/site-packages/django/db/models/query.py", line 91, in __iter__
    results = compiler.execute_sql(
  File "/home/sabbir/zenith-sys/zenith/.venv/lib/python3.10/site-packages/django/db/models/sql/compiler.py", line 1560, in execute_sql
    cursor = self.connection.cursor()
  File "/home/sabbir/zenith-sys/zenith/.venv/lib/python3.10/site-packages/django/utils/asyncio.py", line 26, in inner
    return func(*args, **kwargs)
  File "/home/sabbir/zenith-sys/zenith/.venv/lib/python3.10/site-packages/django/db/backends/base/base.py", line 330, in cursor
    return self._cursor()
  File "/home/sabbir/zenith-sys/zenith/.venv/lib/python3.10/site-packages/django/db/backends/base/base.py", line 306, in _cursor
    self.ensure_connection()
  File "/home/sabbir/zenith-sys/zenith/.venv/lib/python3.10/site-packages/django/utils/asyncio.py", line 26, in inner
    return func(*args, **kwargs)
  File "/home/sabbir/zenith-sys/zenith/.venv/lib/python3.10/site-packages/django/db/backends/base/base.py", line 288, in ensure_connection
    with self.wrap_database_errors:
  File "/home/sabbir/zenith-sys/zenith/.venv/lib/python3.10/site-packages/django/db/utils.py", line 91, in __exit__
    raise dj_exc_value.with_traceback(traceback) from exc_value
  File "/home/sabbir/zenith-sys/zenith/.venv/lib/python3.10/site-packages/django/db/backends/base/base.py", line 289, in ensure_connection
    self.connect()
  File "/home/sabbir/zenith-sys/zenith/.venv/lib/python3.10/site-packages/django/utils/asyncio.py", line 26, in inner
    return func(*args, **kwargs)
  File "/home/sabbir/zenith-sys/zenith/.venv/lib/python3.10/site-packages/django/db/backends/base/base.py", line 270, in connect
    self.connection = self.get_new_connection(conn_params)
  File "/home/sabbir/zenith-sys/zenith/.venv/lib/python3.10/site-packages/django/utils/asyncio.py", line 26, in inner
    return func(*args, **kwargs)
  File "/home/sabbir/zenith-sys/zenith/.venv/lib/python3.10/site-packages/django/db/backends/postgresql/base.py", line 275, in get_new_connection
    connection = self.Database.connect(**conn_params)
  File "/home/sabbir/zenith-sys/zenith/.venv/lib/python3.10/site-packages/psycopg2/__init__.py", line 122, in connect
    conn = _connect(dsn, connection_factory=connection_factory, **kwasync)
django.db.utils.OperationalError: could not translate host name "postgres" to address: Name or service not known

2024-02-03 07:30:27,760 (ERROR) - django.request - Internal Server Error: /api/iot/ws/AC118/
Traceback (most recent call last):
  File "/home/sabbir/zenith-sys/zenith/.venv/lib/python3.10/site-packages/django/db/backends/base/base.py", line 289, in ensure_connection
    self.connect()
  File "/home/sabbir/zenith-sys/zenith/.venv/lib/python3.10/site-packages/django/utils/asyncio.py", line 26, in inner
    return func(*args, **kwargs)
  File "/home/sabbir/zenith-sys/zenith/.venv/lib/python3.10/site-packages/django/db/backends/base/base.py", line 270, in connect
    self.connection = self.get_new_connection(conn_params)
  File "/home/sabbir/zenith-sys/zenith/.venv/lib/python3.10/site-packages/django/utils/asyncio.py", line 26, in inner
    return func(*args, **kwargs)
  File "/home/sabbir/zenith-sys/zenith/.venv/lib/python3.10/site-packages/django/db/backends/postgresql/base.py", line 275, in get_new_connection
    connection = self.Database.connect(**conn_params)
  File "/home/sabbir/zenith-sys/zenith/.venv/lib/python3.10/site-packages/psycopg2/__init__.py", line 122, in connect
    conn = _connect(dsn, connection_factory=connection_factory, **kwasync)
psycopg2.OperationalError: could not translate host name "postgres" to address: Name or service not known


The above exception was the direct cause of the following exception:

Traceback (most recent call last):
  File "/home/sabbir/zenith-sys/zenith/.venv/lib/python3.10/site-packages/asgiref/sync.py", line 534, in thread_handler
    raise exc_info[1]
  File "/home/sabbir/zenith-sys/zenith/.venv/lib/python3.10/site-packages/django/core/handlers/exception.py", line 42, in inner
    response = await get_response(request)
  File "/home/sabbir/zenith-sys/zenith/.venv/lib/python3.10/site-packages/django/core/handlers/base.py", line 253, in _get_response_async
    response = await wrapped_callback(
  File "/home/sabbir/zenith-sys/zenith/.venv/lib/python3.10/site-packages/asgiref/sync.py", line 479, in __call__
    ret: _R = await loop.run_in_executor(
  File "/home/sabbir/zenith-sys/zenith/.venv/lib/python3.10/site-packages/asgiref/current_thread_executor.py", line 40, in run
    result = self.fn(*self.args, **self.kwargs)
  File "/home/sabbir/zenith-sys/zenith/.venv/lib/python3.10/site-packages/asgiref/sync.py", line 538, in thread_handler
    return func(*args, **kwargs)
  File "/home/sabbir/zenith-sys/zenith/.venv/lib/python3.10/site-packages/django/views/generic/base.py", line 104, in view
    return self.dispatch(request, *args, **kwargs)
  File "/home/sabbir/zenith-sys/zenith/.venv/lib/python3.10/site-packages/django/views/generic/base.py", line 143, in dispatch
    return handler(request, *args, **kwargs)
  File "/home/sabbir/zenith-sys/zenith/.venv/lib/python3.10/site-packages/django/views/generic/base.py", line 226, in get
    context = self.get_context_data(**kwargs)
  File "/home/sabbir/zenith-sys/zenith/iot/views.py", line 43, in get_context_data
    topic = Device.objects.get(client_id=device_id).topic
  File "/home/sabbir/zenith-sys/zenith/.venv/lib/python3.10/site-packages/django/db/models/manager.py", line 87, in manager_method
    return getattr(self.get_queryset(), name)(*args, **kwargs)
  File "/home/sabbir/zenith-sys/zenith/.venv/lib/python3.10/site-packages/django/db/models/query.py", line 633, in get
    num = len(clone)
  File "/home/sabbir/zenith-sys/zenith/.venv/lib/python3.10/site-packages/django/db/models/query.py", line 380, in __len__
    self._fetch_all()
  File "/home/sabbir/zenith-sys/zenith/.venv/lib/python3.10/site-packages/django/db/models/query.py", line 1881, in _fetch_all
    self._result_cache = list(self._iterable_class(self))
  File "/home/sabbir/zenith-sys/zenith/.venv/lib/python3.10/site-packages/django/db/models/query.py", line 91, in __iter__
    results = compiler.execute_sql(
  File "/home/sabbir/zenith-sys/zenith/.venv/lib/python3.10/site-packages/django/db/models/sql/compiler.py", line 1560, in execute_sql
    cursor = self.connection.cursor()
  File "/home/sabbir/zenith-sys/zenith/.venv/lib/python3.10/site-packages/django/utils/asyncio.py", line 26, in inner
    return func(*args, **kwargs)
  File "/home/sabbir/zenith-sys/zenith/.venv/lib/python3.10/site-packages/django/db/backends/base/base.py", line 330, in cursor
    return self._cursor()
  File "/home/sabbir/zenith-sys/zenith/.venv/lib/python3.10/site-packages/django/db/backends/base/base.py", line 306, in _cursor
    self.ensure_connection()
  File "/home/sabbir/zenith-sys/zenith/.venv/lib/python3.10/site-packages/django/utils/asyncio.py", line 26, in inner
    return func(*args, **kwargs)
  File "/home/sabbir/zenith-sys/zenith/.venv/lib/python3.10/site-packages/django/db/backends/base/base.py", line 288, in ensure_connection
    with self.wrap_database_errors:
  File "/home/sabbir/zenith-sys/zenith/.venv/lib/python3.10/site-packages/django/db/utils.py", line 91, in __exit__
    raise dj_exc_value.with_traceback(traceback) from exc_value
  File "/home/sabbir/zenith-sys/zenith/.venv/lib/python3.10/site-packages/django/db/backends/base/base.py", line 289, in ensure_connection
    self.connect()
  File "/home/sabbir/zenith-sys/zenith/.venv/lib/python3.10/site-packages/django/utils/asyncio.py", line 26, in inner
    return func(*args, **kwargs)
  File "/home/sabbir/zenith-sys/zenith/.venv/lib/python3.10/site-packages/django/db/backends/base/base.py", line 270, in connect
    self.connection = self.get_new_connection(conn_params)
  File "/home/sabbir/zenith-sys/zenith/.venv/lib/python3.10/site-packages/django/utils/asyncio.py", line 26, in inner
    return func(*args, **kwargs)
  File "/home/sabbir/zenith-sys/zenith/.venv/lib/python3.10/site-packages/django/db/backends/postgresql/base.py", line 275, in get_new_connection
    connection = self.Database.connect(**conn_params)
  File "/home/sabbir/zenith-sys/zenith/.venv/lib/python3.10/site-packages/psycopg2/__init__.py", line 122, in connect
    conn = _connect(dsn, connection_factory=connection_factory, **kwasync)
django.db.utils.OperationalError: could not translate host name "postgres" to address: Name or service not known

2024-02-03 08:57:26,643 (INFO) - iot.channels.consumers - WebSocket connected: specific.7e884df49f0e412e899eed80d5f98abd!7f6106d53384487da83fe0191e3dde50
2024-02-03 08:57:26,820 (INFO) - iot.channels.consumers - mqtt_client_task initiated for device: AC118
2024-02-03 08:59:19,394 (INFO) - iot.channels.consumers - WebSocket disconnected: specific.7e884df49f0e412e899eed80d5f98abd!7f6106d53384487da83fe0191e3dde50
2024-02-03 08:59:24,236 (INFO) - iot.channels.consumers - WebSocket connected: specific.683c1ac431d64d4c9f407608106285b2!149d29ae9ef44afa8ea4795453324fb4
2024-02-03 08:59:24,357 (INFO) - iot.channels.consumers - mqtt_client_task initiated for device: AC118
2024-02-03 08:59:56,680 (INFO) - iot.channels.consumers - WebSocket disconnected: specific.683c1ac431d64d4c9f407608106285b2!149d29ae9ef44afa8ea4795453324fb4
2024-02-03 09:00:01,564 (INFO) - iot.channels.consumers - WebSocket connected: specific.d0eb1abb30dc4de7a02cca6da249c405!1da8b8dfb8a84cbc9a7c83cacd2c507e
2024-02-03 09:00:01,675 (INFO) - iot.channels.consumers - mqtt_client_task initiated for device: AC118
2024-02-03 09:00:54,587 (INFO) - iot.channels.consumers - WebSocket disconnected: specific.d0eb1abb30dc4de7a02cca6da249c405!1da8b8dfb8a84cbc9a7c83cacd2c507e
2024-02-03 09:00:58,368 (INFO) - iot.channels.consumers - WebSocket connected: specific.0670cf432247493cbf3ab37b939ec7d3!aa4d1c12bbaf42ff96c26d9d5eaa0daf
2024-02-03 09:00:58,505 (INFO) - iot.channels.consumers - mqtt_client_task initiated for device: AC118
2024-02-03 09:01:14,060 (INFO) - iot.channels.consumers - WebSocket disconnected: specific.0670cf432247493cbf3ab37b939ec7d3!aa4d1c12bbaf42ff96c26d9d5eaa0daf
2024-02-03 09:01:17,373 (INFO) - iot.channels.consumers - WebSocket connected: specific.d6cb3084e7884d14b02915194c3fd9fe!e12c4af0f1ce4976a87bafae0014461d
2024-02-03 09:01:17,515 (INFO) - iot.channels.consumers - mqtt_client_task initiated for device: AC118
2024-02-03 09:03:06,486 (INFO) - iot.channels.consumers - WebSocket disconnected: specific.d6cb3084e7884d14b02915194c3fd9fe!e12c4af0f1ce4976a87bafae0014461d
2024-02-03 09:03:17,214 (INFO) - iot.channels.consumers - WebSocket connected: specific.5e13a92b0e744a85b5ac4523eb223e96!44e933afbea245909dbcecac6dde15d2
2024-02-03 09:03:17,428 (INFO) - iot.channels.consumers - mqtt_client_task initiated for device: AC118
2024-02-03 09:05:21,696 (INFO) - iot.channels.consumers - WebSocket disconnected: specific.5e13a92b0e744a85b5ac4523eb223e96!44e933afbea245909dbcecac6dde15d2
2024-02-03 09:07:23,235 (INFO) - iot.channels.consumers - WebSocket connected: specific.fa4dccc54596409ba15e0d3f78c40e73!164ca94044ac421db11ca8526ad5e4d5
2024-02-03 09:07:23,423 (INFO) - iot.channels.consumers - mqtt_client_task initiated for device: AC118
2024-02-03 09:12:45,154 (INFO) - iot.channels.consumers - WebSocket disconnected: specific.fa4dccc54596409ba15e0d3f78c40e73!164ca94044ac421db11ca8526ad5e4d5
2024-02-03 09:13:06,344 (INFO) - iot.channels.consumers - WebSocket connected: specific.43d18ac8db334f55a91a983c9e5c04f1!1125571f82ab4aa6a0b421a508e9bb84
2024-02-03 09:13:06,505 (INFO) - iot.channels.consumers - mqtt_client_task initiated for device: AC118
2024-02-03 09:13:21,269 (INFO) - iot.channels.consumers - WebSocket disconnected: specific.43d18ac8db334f55a91a983c9e5c04f1!1125571f82ab4aa6a0b421a508e9bb84
2024-02-03 09:13:21,564 (INFO) - iot.channels.consumers - WebSocket connected: specific.43d18ac8db334f55a91a983c9e5c04f1!67e5289b398a4a03b89153be8029426f
2024-02-03 09:13:21,615 (INFO) - iot.channels.consumers - mqtt_client_task initiated for device: AC118
2024-02-03 09:14:28,270 (INFO) - iot.channels.consumers - WebSocket connected: specific.43d18ac8db334f55a91a983c9e5c04f1!2f3468a5d99544d689e587a46cb9c048
2024-02-03 09:14:28,278 (INFO) - iot.channels.consumers - mqtt_client_task initiated for device: AC118
2024-02-03 09:14:37,359 (INFO) - iot.channels.consumers - WebSocket disconnected: specific.43d18ac8db334f55a91a983c9e5c04f1!2f3468a5d99544d689e587a46cb9c048
2024-02-03 09:14:37,783 (INFO) - iot.channels.consumers - WebSocket connected: specific.43d18ac8db334f55a91a983c9e5c04f1!bcefb86346b94dae81258fefddf62d39
2024-02-03 09:14:37,790 (INFO) - iot.channels.consumers - mqtt_client_task initiated for device: AC118
2024-02-03 09:15:25,543 (INFO) - iot.channels.consumers - WebSocket connected: specific.43d18ac8db334f55a91a983c9e5c04f1!2a9feccf5d854f0fa5611f2a77d33458
2024-02-03 09:15:25,549 (INFO) - iot.channels.consumers - mqtt_client_task initiated for device: AC118
2024-02-03 09:15:46,390 (INFO) - iot.channels.consumers - WebSocket disconnected: specific.43d18ac8db334f55a91a983c9e5c04f1!2a9feccf5d854f0fa5611f2a77d33458
2024-02-03 09:15:55,800 (INFO) - iot.channels.consumers - WebSocket disconnected: specific.43d18ac8db334f55a91a983c9e5c04f1!bcefb86346b94dae81258fefddf62d39
2024-02-03 09:15:56,216 (INFO) - iot.channels.consumers - WebSocket connected: specific.43d18ac8db334f55a91a983c9e5c04f1!1d49da18f75e4afd978594cc0429abd9
2024-02-03 09:15:56,230 (INFO) - iot.channels.consumers - mqtt_client_task initiated for device: AC118
2024-02-03 09:17:59,815 (INFO) - iot.channels.consumers - WebSocket disconnected: specific.43d18ac8db334f55a91a983c9e5c04f1!1d49da18f75e4afd978594cc0429abd9
2024-02-03 09:17:59,816 (INFO) - iot.channels.consumers - WebSocket disconnected: specific.43d18ac8db334f55a91a983c9e5c04f1!67e5289b398a4a03b89153be8029426f
2024-02-03 09:18:59,903 (INFO) - iot.channels.consumers - WebSocket connected: specific.3f3d2c98439b41e68581f05870e093db!ac458fe0c4544ec8a872098c4309373b
2024-02-03 09:19:00,130 (INFO) - iot.channels.consumers - mqtt_client_task initiated for device: AC118
2024-02-03 09:20:34,948 (INFO) - iot.channels.consumers - WebSocket disconnected: specific.3f3d2c98439b41e68581f05870e093db!ac458fe0c4544ec8a872098c4309373b
2024-02-03 09:20:45,493 (INFO) - iot.channels.consumers - WebSocket connected: specific.0a56d27812ed4fe9b5eef70be18f3468!d68a77e4104243ae8d5a3952f3fbb51d
2024-02-03 09:20:45,643 (INFO) - iot.channels.consumers - mqtt_client_task initiated for device: AC118
2024-02-03 09:21:09,725 (INFO) - iot.channels.consumers - WebSocket disconnected: specific.0a56d27812ed4fe9b5eef70be18f3468!d68a77e4104243ae8d5a3952f3fbb51d
2024-02-03 09:21:13,340 (INFO) - iot.channels.consumers - WebSocket connected: specific.05a6e662a65a4a1188e31479e1581d74!b4f4ab83dde64b1485a8fbb452f814cf
2024-02-03 09:21:13,454 (INFO) - iot.channels.consumers - mqtt_client_task initiated for device: AC118
2024-02-03 09:21:35,927 (INFO) - iot.channels.consumers - WebSocket disconnected: specific.05a6e662a65a4a1188e31479e1581d74!b4f4ab83dde64b1485a8fbb452f814cf
2024-02-03 09:24:20,018 (INFO) - iot.channels.consumers - WebSocket connected: specific.adea1e9bdaef4facb6b13feefc8a5cd9!10a531d455aa47d3bae91888b565f621
2024-02-03 09:24:20,083 (INFO) - iot.channels.consumers - mqtt_client_task initiated for device: AC118
2024-02-03 09:25:02,058 (INFO) - iot.channels.consumers - WebSocket disconnected: specific.adea1e9bdaef4facb6b13feefc8a5cd9!10a531d455aa47d3bae91888b565f621
2024-02-03 09:27:09,212 (INFO) - iot.channels.consumers - WebSocket connected: specific.adea1e9bdaef4facb6b13feefc8a5cd9!0d4b8470a5d546bba5b4d0ce93b27ef1
2024-02-03 09:27:09,230 (INFO) - iot.channels.consumers - mqtt_client_task initiated for device: AC118
2024-02-03 09:27:33,809 (INFO) - iot.channels.consumers - WebSocket disconnected: specific.adea1e9bdaef4facb6b13feefc8a5cd9!0d4b8470a5d546bba5b4d0ce93b27ef1
2024-02-03 09:31:14,564 (INFO) - iot.channels.consumers - WebSocket connected: specific.3e22f894859b4c11a793fe0b81e2ff61!f17ae43a99a14ba9b5daed000da65e24
2024-02-03 09:31:14,660 (INFO) - iot.channels.consumers - mqtt_client_task initiated for device: AC118
2024-02-03 09:31:43,292 (INFO) - iot.channels.consumers - WebSocket disconnected: specific.3e22f894859b4c11a793fe0b81e2ff61!f17ae43a99a14ba9b5daed000da65e24
2024-02-03 09:31:54,650 (INFO) - iot.channels.consumers - WebSocket connected: specific.35a1a06b84e944c59fa332a873806dd6!7032552bc01649308469bcbd6e22e86f
2024-02-03 09:31:54,751 (INFO) - iot.channels.consumers - mqtt_client_task initiated for device: AC118
2024-02-03 09:35:30,453 (INFO) - iot.channels.consumers - WebSocket disconnected: specific.35a1a06b84e944c59fa332a873806dd6!7032552bc01649308469bcbd6e22e86f
2024-02-03 09:36:40,939 (INFO) - iot.channels.consumers - WebSocket connected: specific.bd9865af837b4b21a2e0b99f49dd0e5f!8aea20a2850741c19f6e0bf8fb64ef6a
2024-02-03 09:36:59,491 (INFO) - iot.channels.consumers - WebSocket connected: specific.6ca34219f05d4e53a9ad6f80d42c26a0!3c05439130a44d3f9a2e5872f1ef0fe1
2024-02-03 09:38:32,850 (INFO) - iot.channels.consumers - WebSocket connected: specific.ecabede27478485791eec9b7087f39ae!bf50ce21c48841c79c80d33310cc9685
2024-02-03 15:58:53,394 (ERROR) - django.request - Internal Server Error: /api/iot/ws/AC119/
Traceback (most recent call last):
  File "/home/sabbir/zenith-sys/zenith/.venv/lib/python3.10/site-packages/asgiref/sync.py", line 534, in thread_handler
    raise exc_info[1]
  File "/home/sabbir/zenith-sys/zenith/.venv/lib/python3.10/site-packages/django/core/handlers/exception.py", line 42, in inner
    response = await get_response(request)
  File "/home/sabbir/zenith-sys/zenith/.venv/lib/python3.10/site-packages/django/core/handlers/base.py", line 253, in _get_response_async
    response = await wrapped_callback(
  File "/home/sabbir/zenith-sys/zenith/.venv/lib/python3.10/site-packages/asgiref/sync.py", line 479, in __call__
    ret: _R = await loop.run_in_executor(
  File "/home/sabbir/zenith-sys/zenith/.venv/lib/python3.10/site-packages/asgiref/current_thread_executor.py", line 40, in run
    result = self.fn(*self.args, **self.kwargs)
  File "/home/sabbir/zenith-sys/zenith/.venv/lib/python3.10/site-packages/asgiref/sync.py", line 538, in thread_handler
    return func(*args, **kwargs)
  File "/home/sabbir/zenith-sys/zenith/.venv/lib/python3.10/site-packages/django/views/generic/base.py", line 104, in view
    return self.dispatch(request, *args, **kwargs)
  File "/home/sabbir/zenith-sys/zenith/.venv/lib/python3.10/site-packages/django/views/generic/base.py", line 143, in dispatch
    return handler(request, *args, **kwargs)
  File "/home/sabbir/zenith-sys/zenith/.venv/lib/python3.10/site-packages/django/views/generic/base.py", line 226, in get
    context = self.get_context_data(**kwargs)
  File "/home/sabbir/zenith-sys/zenith/iot/views.py", line 43, in get_context_data
    topic = Device.objects.get(client_id=device_id).topic
  File "/home/sabbir/zenith-sys/zenith/.venv/lib/python3.10/site-packages/django/db/models/manager.py", line 87, in manager_method
    return getattr(self.get_queryset(), name)(*args, **kwargs)
  File "/home/sabbir/zenith-sys/zenith/.venv/lib/python3.10/site-packages/django/db/models/query.py", line 647, in get
    raise self.model.DoesNotExist(
iot.models.Device.DoesNotExist: Device matching query does not exist.
2024-02-03 16:07:57,366 (WARNING) - django.request - Not Found: /api/iot/ws/AC118/l
2024-02-03 16:14:07,736 (WARNING) - django.request - Not Found: /api/iot/ws/AC118/l
2024-02-03 16:20:22,779 (WARNING) - django.request - Not Found: /favicon.ico
2024-02-03 16:24:00,607 (WARNING) - django.request - Not Found: /api/iot/ws/AC118/l
2024-02-03 17:17:24,297 (WARNING) - django.request - Not Found: /api/iot/ws/AC118/jk
2024-02-03 17:29:01,377 (WARNING) - django.request - Not Found: /api/iot/ws/AC118/jk
2024-02-03 17:47:18,298 (WARNING) - django.request - Not Found: /api/iot/ws/AC118//
2024-02-03 17:47:18,419 (WARNING) - django.request - Not Found: /favicon.ico
2024-02-03 17:58:57,479 (WARNING) - django.request - Bad Request: /auth/jwt/verify/
2024-02-03 17:58:57,492 (WARNING) - django.request - Bad Request: /auth/jwt/verify/
2024-02-03 17:59:04,659 (WARNING) - django.request - Unauthorized: /auth/jwt/create/
2024-02-03 17:59:04,675 (WARNING) - django.request - Bad Request: /auth/jwt/refresh/
2024-02-03 18:01:56,406 (WARNING) - django.request - Bad Request: /auth/jwt/verify/
2024-02-03 18:01:56,429 (WARNING) - django.request - Bad Request: /auth/jwt/verify/
2024-02-03 18:02:25,933 (WARNING) - django.request - Not Found: /api/guests/
2024-02-03 18:02:39,618 (WARNING) - django.request - Not Found: /api/guests/
2024-02-03 18:03:24,691 (WARNING) - django.request - Not Found: /api/guests/
2024-02-03 18:03:34,247 (WARNING) - django.request - Not Found: /api/guests/
2024-02-03 18:04:54,477 (WARNING) - django.request - Not Found: /api/
2024-02-03 18:05:03,120 (WARNING) - django.request - Unauthorized: /api/main/guests/
2024-02-03 18:05:23,469 (WARNING) - django.request - Forbidden: /api/main/guests/
2024-02-03 18:05:53,931 (WARNING) - django.request - Forbidden: /api/main/guests/
2024-02-03 18:05:54,196 (WARNING) - django.request - Not Found: /favicon.ico
2024-02-03 18:06:06,111 (WARNING) - django.request - Unauthorized: /api/main/guests/
2024-02-03 18:06:25,527 (WARNING) - django.request - Forbidden: /api/main/guests/
2024-02-03 18:11:21,293 (ERROR) - django.request - Internal Server Error: /admin/main/payment/add/
Traceback (most recent call last):
  File "/home/sabbir/zenith-sys/zenith/.venv/lib/python3.10/site-packages/django/contrib/admin/options.py", line 835, in get_form
    return modelform_factory(self.model, **defaults)
  File "/home/sabbir/zenith-sys/zenith/.venv/lib/python3.10/site-packages/django/forms/models.py", line 651, in modelform_factory
    return type(form)(class_name, (form,), form_class_attrs)
  File "/home/sabbir/zenith-sys/zenith/.venv/lib/python3.10/site-packages/django/forms/models.py", line 309, in __new__
    fields = fields_for_model(
  File "/home/sabbir/zenith-sys/zenith/.venv/lib/python3.10/site-packages/django/forms/models.py", line 204, in fields_for_model
    raise FieldError(
django.core.exceptions.FieldError: 'created_at' cannot be specified for Payment model form as it is a non-editable field

During handling of the above exception, another exception occurred:

Traceback (most recent call last):
  File "/home/sabbir/zenith-sys/zenith/.venv/lib/python3.10/site-packages/asgiref/sync.py", line 534, in thread_handler
    raise exc_info[1]
  File "/home/sabbir/zenith-sys/zenith/.venv/lib/python3.10/site-packages/django/core/handlers/exception.py", line 42, in inner
    response = await get_response(request)
  File "/home/sabbir/zenith-sys/zenith/.venv/lib/python3.10/site-packages/django/core/handlers/base.py", line 253, in _get_response_async
    response = await wrapped_callback(
  File "/home/sabbir/zenith-sys/zenith/.venv/lib/python3.10/site-packages/asgiref/sync.py", line 479, in __call__
    ret: _R = await loop.run_in_executor(
  File "/home/sabbir/zenith-sys/zenith/.venv/lib/python3.10/site-packages/asgiref/current_thread_executor.py", line 40, in run
    result = self.fn(*self.args, **self.kwargs)
  File "/home/sabbir/zenith-sys/zenith/.venv/lib/python3.10/site-packages/asgiref/sync.py", line 538, in thread_handler
    return func(*args, **kwargs)
  File "/home/sabbir/zenith-sys/zenith/.venv/lib/python3.10/site-packages/django/contrib/admin/options.py", line 714, in wrapper
    return self.admin_site.admin_view(view)(*args, **kwargs)
  File "/home/sabbir/zenith-sys/zenith/.venv/lib/python3.10/site-packages/django/utils/decorators.py", line 188, in _view_wrapper
    result = _process_exception(request, e)
  File "/home/sabbir/zenith-sys/zenith/.venv/lib/python3.10/site-packages/django/utils/decorators.py", line 186, in _view_wrapper
    response = view_func(request, *args, **kwargs)
  File "/home/sabbir/zenith-sys/zenith/.venv/lib/python3.10/site-packages/django/views/decorators/cache.py", line 80, in _view_wrapper
    response = view_func(request, *args, **kwargs)
  File "/home/sabbir/zenith-sys/zenith/.venv/lib/python3.10/site-packages/django/contrib/admin/sites.py", line 240, in inner
    return view(request, *args, **kwargs)
  File "/home/sabbir/zenith-sys/zenith/.venv/lib/python3.10/site-packages/django/contrib/admin/options.py", line 1941, in add_view
    return self.changeform_view(request, None, form_url, extra_context)
  File "/home/sabbir/zenith-sys/zenith/.venv/lib/python3.10/site-packages/django/utils/decorators.py", line 48, in _wrapper
    return bound_method(*args, **kwargs)
  File "/home/sabbir/zenith-sys/zenith/.venv/lib/python3.10/site-packages/django/utils/decorators.py", line 188, in _view_wrapper
    result = _process_exception(request, e)
  File "/home/sabbir/zenith-sys/zenith/.venv/lib/python3.10/site-packages/django/utils/decorators.py", line 186, in _view_wrapper
    response = view_func(request, *args, **kwargs)
  File "/home/sabbir/zenith-sys/zenith/.venv/lib/python3.10/site-packages/django/contrib/admin/options.py", line 1802, in changeform_view
    return self._changeform_view(request, object_id, form_url, extra_context)
  File "/home/sabbir/zenith-sys/zenith/.venv/lib/python3.10/site-packages/django/contrib/admin/options.py", line 1837, in _changeform_view
    ModelForm = self.get_form(
  File "/home/sabbir/zenith-sys/zenith/.venv/lib/python3.10/site-packages/django/contrib/admin/options.py", line 837, in get_form
    raise FieldError(
django.core.exceptions.FieldError: 'created_at' cannot be specified for Payment model form as it is a non-editable field. Check fields/fieldsets/exclude attributes of class PaymentAdmin.
2024-02-04 15:57:35,610 (WARNING) - django.request - Not Found: /favicon.ico
